Workbook

Sheet Parameters
A2: Production function
A3: δ | B3: 0.04 | C3: decay rate of capital | M3: MAC | Q3: TAC
A4: δ+g_L+g | B4: =B3+B53+B51 -> 0.0629 | C4: decay rate of capital per unit of effective labour | L4: emissions | M4: Model | N4: MedianIPCC | O4: P25_IPCC | P4: P75_IPCC | Q4: Model | R4: MedianIPCC | S4: P25_IPCC | T4: P75_IPCC
A5: χ | B5: 1 | C5: investment adjustment cost | L5: -2.5 | M5: =_xlfn.XLOOKUP($L5,'6states'!$L$4:$L$154,'6states'!BA$4:BA$154,,-1) -> #N/A | N5: 830.6485 | O5: 534.3041 | P5: 1319.8 | Q5: =_xlfn.XLOOKUP($L5,'6states'!$L$4:$L$104,'6states'!AR$4:AR$104,,-1) -> #N/A | R5: 0.0282474 | S5: 0.0203494 | T5: 0.0396778
A6: χ_s | B6: 5 | C6: investment adjustment cost for negative investments | L6: 2.5 | M6: =_xlfn.XLOOKUP($L6,'6states'!$L$4:$L$154,'6states'!BA$4:BA$154,,-1) -> 2701.6073 | N6: 606.6119 | O6: 387.1183 | P6: 1117.905 | Q6: =_xlfn.XLOOKUP($L6,'6states'!$L$4:$L$104,'6states'!AR$4:AR$104,,-1) -> #N/A | R6: 0.0266951 | S6: 0.0180696 | T6: 0.0408597
A7: α | B7: 0.3 | C7: share of capital income in national income | L7: 7.5 | M7: =_xlfn.XLOOKUP($L7,'6states'!$L$4:$L$154,'6states'!BA$4:BA$154,,-1) -> 819.76523 | N7: 417.0838 | O7: 242.3764 | P7: 684.3727 | Q7: =_xlfn.XLOOKUP($L7,'6states'!$L$4:$L$104,'6states'!AX$4:AX$104,,-1) -> 0.094165303 | R7: 0.0196925 | S7: 0.0123111 | T7: 0.0283897
A8: σ_f | B8: 0.2 | C8: elasticity of substitution between energy and final capital | L8: 12.5 | M8: =_xlfn.XLOOKUP($L8,'6states'!$L$4:$L$154,'6states'!BA$4:BA$154,,-1) -> 513.1788 | N8: 369.451 | O8: 259.5315 | P8: 657.7192 | Q8: =_xlfn.XLOOKUP($L8,'6states'!$L$4:$L$104,'6states'!AX$4:AX$104,,-1) -> 0.087999722 | R8: 0.0201464 | S8: 0.0142053 | T8: 0.0303724
A9: ε_f | B9: =1-1/B8 -> -4 | C9: 1-1/sigma | L9: 17.5 | M9: =_xlfn.XLOOKUP($L9,'6states'!$L$4:$L$154,'6states'!BA$4:BA$154,,-1) -> 372.20983 | N9: 279.1021 | O9: 194.9201 | P9: 471.1751 | Q9: =_xlfn.XLOOKUP($L9,'6states'!$L$4:$L$104,'6states'!AX$4:AX$104,,-1) -> 0.077164021 | R9: 0.0194575 | S9: 0.0137847 | T9: 0.0288798
A10: φ_f | B10: =1-B11 -> 0.99994397 | C10: share parameter of final-good capital | L10: 22.5 | M10: =_xlfn.XLOOKUP($L10,'6states'!$L$4:$L$154,'6states'!BA$4:BA$154,,-1) -> 274.09097 | N10: 201.3134 | O10: 145.1962 | P10: 330 | Q10: =_xlfn.XLOOKUP($L10,'6states'!$L$4:$L$104,'6states'!AX$4:AX$104,,-1) -> 0.060566036 | R10: 0.0183307 | S10: 0.0123982 | T10: 0.0285
A11: φ_E | B11: =1/(1+(B18*B16^B13+B19*B14^B13)^(B9/B13-1)*B18*B16^(B13-1)) -> 5.603267e-05 | C11: share parameter of energy capital, using Y_k_f=Y_k_c | L11: 27.5 | M11: =_xlfn.XLOOKUP($L11,'6states'!$L$4:$L$154,'6states'!BA$4:BA$154,,-1) -> 226.11165 | N11: 158.2803 | O11: 107.6669 | P11: 245.52 | Q11: =_xlfn.XLOOKUP($L11,'6states'!$L$4:$L$104,'6states'!AX$4:AX$104,,-1) -> 0.04190191 | R11: 0.0160009 | S11: 0.0110032 | T11: 0.0237186
A12: σ[0] | B12: 2 | C12: elasticity of substitution between clean and dirty capital in energy sector (initially 2) | L12: 32.5 | M12: =_xlfn.XLOOKUP($L12,'6states'!$L$4:$L$154,'6states'!BA$4:BA$154,,-1) -> 210.18249 | N12: 112.6412 | O12: 81.44473 | P12: 177.918 | Q12: =_xlfn.XLOOKUP($L12,'6states'!$L$4:$L$104,'6states'!AX$4:AX$104,,-1) -> 0.030196495 | R12: 0.0121626 | S12: 0.008787 | T12: 0.0173682
A13: ε[0] | B13: =1-1/B12 -> 0.5 | C13: 1-1/sigma | L13: 37.5 | M13: =_xlfn.XLOOKUP($L13,'6states'!$L$4:$L$154,'6states'!BA$4:BA$154,,-1) -> 195.2725 | N13: 89.53163 | O13: 58.81897 | P13: 159.2609 | Q13: =_xlfn.XLOOKUP($L13,'6states'!$L$4:$L$104,'6states'!AX$4:AX$104,,-1) -> 0.016993446 | R13: 0.0082251 | S13: 0.0056994 | T13: 0.0138741
A14: θ_d | B14: 0.1841 | C14: ratio of dirty capital over final capital (k_d+xi)/k_f | L14: 42.5 | M14: =_xlfn.XLOOKUP($L14,'6states'!$L$4:$L$154,'6states'!BA$4:BA$154,,-1) -> 185.85283 | N14: 74.8676 | O14: 47.31793 | P14: 131.6824 | Q14: =_xlfn.XLOOKUP($L14,'6states'!$L$4:$L$104,'6states'!AX$4:AX$104,,-1) -> 0.006131762 | R14: 0.006194 | S14: 0.0038782 | T14: 0.0092856
A15: k_c/(k_c+k_d+ξ) | B15: 0.16 | C15: ratio of renewable over all energy from IEA (should be 0.16) | L15: 47.5 | M15: =_xlfn.XLOOKUP($L15,'6states'!$L$4:$L$154,'6states'!BA$4:BA$154,,-1) -> 185.85283 | N15: 32.49194 | O15: 10.02872 | P15: 64.102 | Q15: =_xlfn.XLOOKUP($L15,'6states'!$L$4:$L$104,'6states'!AX$4:AX$104,,-1) -> 0.006131762 | R15: 0.0027149 | S15: 0.0007531 | T15: 0.0051001
A16: θ_c | B16: =B14*B15/(1-B15) -> 0.035066667 | C16: ratio of renewable capital over final capital k_c/k_f | L16: 52.5 | M16: =_xlfn.XLOOKUP($L16,'6states'!$L$4:$L$154,'6states'!BA$4:BA$154,,-1) -> 185.85283 | N16: 1.7695 | O16: 0 | P16: 12.83052 | Q16: =_xlfn.XLOOKUP($L16,'6states'!$L$4:$L$104,'6states'!AX$4:AX$104,,-1) -> 0.006131762 | R16: 0 | S16: 0 | T16: 0.0005013
A17: k_c/(k_d+ξ) | B17: =B16/B14 -> 0.19047619 | C17: ratio of renewable over clean energy | L17: 57.5 | M17: =_xlfn.XLOOKUP($L17,'6states'!$L$4:$L$154,'6states'!BA$4:BA$154,,-1) -> 181.28957 | N17: 2.24156 | O17: 0 | P17: 11.00962 | Q17: =_xlfn.XLOOKUP($L17,'6states'!$L$4:$L$104,'6states'!AX$4:AX$104,,-1) -> 0 | R17: 0 | S17: 0 | T17: 1e-05
A18: φ_c | B18: =1-B19 -> 0.30383243 | C18: share parameter of clean capital | D18: =B18^(1/B13) -> 0.092314148
A19: φ_d | B19: =1/((B17)^(1-B13)+1) -> 0.69616757 | C19: share parameter of dirty capital | D19: =B18^(1/0.77) -> 0.21286109 | L19: Squared Error | M19: =SUMXMY2(M6:M16,N6:N16)/11/1000 -> 425.52744 | Q19: =SUMXMY2(Q7:Q16,R7:R16)/10*10000 -> 16.386383
A20: ξ | B20: 0.01 | C20: shift in the MAC curve (0.01) | L20: combined error | M20: =M19+Q19 -> 441.91382
A21: varespilon | B21: 300 | C21: parameter in softplus function
A22: vareps2 | B22: 0.004 | C22: shift in softplus of stranding (0.004)
A24: Initial states
A25: k_d[0] | B25: =B27*B14-B20 -> 0.790835 | C25: initial dirty capital (ss in constantT&epsilon sheet) | D25: K_d[0] | E25: =B25*B$28*B$29 -> 58.418283 | F25: k_d[0] theory | G25: =B14*G27 -> 1.0792327
A26: k_c[0] | B26: =B27*B16 -> 0.15254 | C26: initial clean capital (ss in constantT&epsilon sheet) | D26: K_c[0] | E26: =B26*B$28*B$29 -> 11.267995 | F26: k_c[0] theory | G26: =B16*G27 -> 0.20556814
A27: k_f[0] | B27: 4.35 | C27: initial final capital (ss in constantT&epsilon sheet) | D27: K_f[0] | E27: =B27*B$28*B$29 -> 321.33066 | F27: k_f[0] theory | G27: =(B7*(B10+B11*(B18*B16^B13+B19*B14^B13)^(B9/B13))^(B7/B9)*EXP(-B46/2*B47^2) / (B56+B5*(B56)^2)) ^ (1/(1-B7)) -> 5.8622094
A28: L[0] | B28: 8.16 | C28: initial Labour | D28: K[0]=(k_f[0]+k_d[0]+k_c[0])*A[0]L[0] | E28: =(B25+B26+B27)*B28*B29 -> 391.01694 | F28: total capital
A29: A[0] | B29: =B30*EXP(B46/2*B47^2)/B28/(Parameters!$B$10*B27^Parameters!$B$9+B11*E30^Parameters!$B$9)^(Parameters!$B$7/Parameters!$B$9) -> 9.0525879 | C29: tfp (targeting Y0) | D29: k_ramsey | E29: =((Parameters!B3+Parameters!B50+Parameters!B52*Parameters!B53)/Parameters!B7)^(1/(Parameters!B7-1)) -> 6.8509746 | F29: k steady state in Ramsey model (without energy)k=((sigma+delta+etag)/alpha)^(1/alpha-1)
A30: Y[0] | B30: 110.98 | C30: initial GDP (trillion $, MERs) | D30: E[0] | E30: =(B18*B26^B13+B19*(B25+B20)^B13)^(1/B13) -> 0.55006251
A31: P_BAU | B31: 53.2 | C31: initial business as usual emissions | D31: k_c/(k_c+k_d) | E31: =B26/(B26+B25) -> 0.16169604 | F31: slightly higher than in theory, due to effect of z
D32: Y_E*E/Y | E32: =B7*B11*E30^(B9-1)/(B10*B27^B9+B11*E30^B9) * E30 -> 0.05393028 | F32: share of energy capital in GDP
D33: Y_kf*kf/Y | E33: =B7*B10*B27^(B9-1)/(B10*B27^B9+B11*E30^B9) * B27 -> 0.24606972 | F33: share of final capital income in GDP
A34: Stranding costs
A35: A[0]L[0]ψ/(σ+g_ψ) | B35: =Parameters!B29*Parameters!B28*Parameters!B41/(Parameters!B3+B42) -> 1345.4134 | C35: cumulative stranded emissions per unit of stranded capital k_s at time zero
A36: Intercept | B36: =6.1198+0.7666 -> 6.8864 | C36: highest carbon intensity in GtCO2/T$, that is kg per $ (sum of a and c from calibration)
A37: ψ_1 | B37: =B36-B39 -> 6.1194186
A38: ψ_2 | B38: 0.729 | C38: degrowth rate of psi as a function of cumulative stranded emissions (calibrated parameter per Billion $ multiplied by 1000)
A39: ψ_3 | B39: =(B31-B36/B38*(1-EXP(-B38*E25)))/(E25-(1-EXP(-B38*E25))/B38) -> 0.76698139
A40: ψ_min | B40: =B37*EXP(-B38*E25)+B39 -> 0.76698139 | C40: lowest emissions intensity of capital at start
A41: \bar{ψ} | B41: =B31/B28/B29/B25 -> 0.9106738 | C41: mean emissions intensity at start
A42: g_ψ | B42: 0.01 | C42: autonomous decrease in carbon intensity
...

Sheet 6states
A1: 6 states: k_f, k_d, k_c, k_s, T, time | BF1: ss lambdaT | BG1: =-W204*X204^(-Parameters!B$52)*Parameters!B$46*Parameters!B$45*N204/Parameters!B45/Parameters!B55 -> -2.5272931
BF2: endog TC missing
A3: Period | B3: Year | C3: i_d[t] | D3: i_c[t] | E3: i_f[t] | F3: k_d[t] | G3: k_c[t] | H3: k_f[t] | I3: k_s[t] | J3: L[t] | K3: A[t] | L3: P[t] | M3: S[t] | N3: T[t] | O3: Ω[t] | P3: M[t]/M[0] | Q3: ω*exp(g_σ)*t | R3: ω*M[t]^-ρ | S3: TC[t] | T3: ε[t] | U3: σ[t] | V3: E[t]/(A[t]*L[t]) | W3: y[t] | X3: c[t] | Y3: β^t | Z3: β^t * u(c[t]) | AA3: W | AC3: I_d[t] | AD3: I_c[t] | AE3: K_s[t] | AF3: K_d[t] | AG3: K_c[t] | AH3: E[t] | AI3: E[t]/E[0] | AJ3: Y[t] | AK3: C[t] | AL3: g_Y[t] | AM3: g_C[t] | AN3: g_Y[t] (5-year moving average) | AO3: g_C[t] (5-year moving average) | AQ3: y_kd-y_kc | AR3: change id ic | AS3: id² ic² | AT3: dP/dKd | AU3: dP/dkd | AV3: MAC[t] | AW3: TAC[t] | AX3: Mgl damage[t] (utils) | AY3: Mgl damage[t] ($) | BA3: SCC[t] | BB3: s[t] | BC3: Dirty adjustment costs (% of investment) | BD3: Clean adj costs (% of investment) | BE3: ratio clean/dirty adj costs | BF3: lambdaS | BG3: lambdaT | BH3: g_lambdaT | BI3: lmbdks-lmbdkd | BJ3: U_c | BK3: dP/dKs | BL3: dP/dks | BM3: ks/(kd+ks) | BN3: dP/Ks-dP/dKd | BS3: lambdaS*dP/dks | BT3: lambdaks | BU3: lambdakc | BV3: g_lambdakc | BW3: lambdakf | BX3: g_lambdakf | BY3: lambdakd | BZ3: g_lambdakd | CA3: d_lambdakd | CB3: elasticity wrt M for LT clean productivity | CC3: E_kc at initial capital ratios | CD3: LR elasticity wrt M for initial clean productivity | CE3: Learning rate | CF3: Learning rate at initial k_j
A4: 0 | B4: 2025 | C4: -0.030791 | D4: 0.037975028 | E4: 0.25186597 | F4: =Parameters!B25 -> 0.790835 | G4: =Parameters!B26 -> 0.15254 | H4: =Parameters!B27 -> 4.35 | I4: 0 | J4: =Parameters!B28 -> 8.16 | K4: =Parameters!B29 -> 9.0525879 | L4: =J4*K4*EXP(-Parameters!$B$42*'6states'!A4)*(Parameters!$B$37/Parameters!$B$38*('6states'!F4+'6states'!I4)/Parameters!$E$25*(EXP(-Parameters!$B$38*Parameters!$E$25*'6states'!I4/('6states'!F4+'6states'!I4))-EXP(-Parameters!$B$38*Parameters!$E$25)) + Parameters!$B$39*'6states'!F4) -> 53.2 | M4: =N4/Parameters!$B$45 -> 2300 | N4: =Parameters!B47 -> 1.38 | O4: =EXP(-Parameters!$B$46/2*N4^2) -> 0.98104277 | P4: =MAX((Parameters!$B$62 + Parameters!$B$31*'6states'!A4 - '6states'!M4 + Parameters!$B$47/Parameters!$B$45)/Parameters!B$62,1) -> 1 | Q4: =Parameters!B$61*EXP(-Parameters!B$60*A4) -> 0.5 | R4: =(1-Parameters!B$61)*P4^-Parameters!B$63 -> 0.5 | S4: =Parameters!B$61*EXP(-Parameters!B$60*A4)+(1-Parameters!B$61)*P4^-Parameters!B$63 -> 1 | T4: =1-S4/Parameters!$B$12 -> 0.5 | U4: =1/(1-T4) -> 2 | V4: =(Parameters!$B$19*(F4+Parameters!$B$20)^T4+Parameters!$B$18*G4^T4)^(1/T4) -> 0.55006251 | W4: =(Parameters!$B$10*H4^Parameters!$B$9+Parameters!$B$11*V4^Parameters!$B$9)^(Parameters!$B$7/Parameters!$B$9)*O4 -> 1.502387 | X4: =W4 - D4 - E4 - LN(1+EXP(Parameters!$B$21*C4))/Parameters!$B$21 - IF(C4>0, 0,Parameters!$B$6*C4^2/F4) -> 1.2065515 | Y4: =EXP(-Parameters!$B$55*A4) -> 1 | Z4: =IF(X4>0,X4^(1-Parameters!$B$52)/(1-Parameters!$B$52)*Y4*Parameters!$B$65,-10+X4*1000) -> -2.6754135 | AA4: =SUM(Z4:Z204)*Parameters!$B$65 -> -185.78348 | AC4: =C4*$J4*$K4 -> -2.274504 | AD4: =D4*$J4*$K4 -> 2.8051818 | AE4: =I4*J4*K4 -> 0 | AF4: =F4*J4*K4 -> 58.418283 | AG4: =G4*J4*K4 -> 11.267995 | AH4: =V4*J4*K4 -> 40.632632 | AI4: =AH4/AH$4*100 -> 100 | AJ4: =W4*J4*K4 -> 110.98 | AK4: =X4*J4*K4 -> 89.126891 | AQ4: =W4*K4*J4 -> 110.98 | AR4: =Parameters!$B$7*W4*(W4/O4)^(-Parameters!$B$9/Parameters!$B$7)*Parameters!$B$11*(V4)^(Parameters!$B$9-T4)*((1-2*Parameters!$B$5*C4/F4)*Parameters!$B$19*(F4+Parameters!$B$20)^(T4-1)-(1-2*Parameters!$B$5*D4/G4)*(Parameters!$B$18)*(G4)^(T4-1)) -> 0.048932949 | AU4: =EXP(-Parameters!$B$42*'6states'!A4)*(Parameters!$B$37*EXP(-Parameters!$B$38*Parameters!$E$25*'6states'!I4/('6states'!F4+'6states'!I4))*(1/Parameters!$B$38/Parameters!$E$25+'6states'!I4/('6states'!F4+'6states'!I4))-Parameters!$B$37/Parameters!$B$38/Parameters!$E$25*EXP(-Parameters!$B$38*Parameters!$E$25)+Parameters!$B$39) -> 0.9106738 | AV4: =J4*K4*EXP(-Parameters!$B$42*'6states'!A4)*(Parameters!$B$37*EXP(-Parameters!$B$38*Parameters!$E$25*'6states'!I4/('6states'!F4+'6states'!I4))*(1/Parameters!$B$38/Parameters!$E$25+'6states'!I4/('6states'!F4+'6states'!I4))-Parameters!$B$37/Parameters!$B$38/Parameters!$E$25*EXP(-Parameters!$B$38*Parameters!$E$25)+Parameters!$B$39) -> 67.27067 | AX4: =1-W4/'6states,ExoDamages'!T4 -> 0 | AZ4: =1000*EXP(-(Parameters!$B$54)*'6states'!A4)*AQ4*Parameters!B$46*Parameters!B$45*N4 -> 1.8470179 | BA4: =SUM(AZ4:AZ$204)*EXP(Parameters!$B$54*A4) -> 181.28957 | BB4: =((C4>0)*C4+D4+E4)/W4 -> 0.19292033 | BC4: =Parameters!$B$6*C4/F4 -> -0.19467399 | BD4: =Parameters!$B$5*D4/G4 -> 0.24895128 | BE4: =(1-2*BD4)/(1-2*BC4) -> 0.3613907 | BF4: =SUM(AY4:AY202)/Y4 -> -0.0018421522 | BG4: =BF4/Parameters!$B$45 -> -3.0702537 | BI4: =-2*Parameters!B$6 * C4/F4*X4^-Parameters!B$52 -> 0.30216977 | BJ4: =X4^-Parameters!B$52 -> 0.77609181 | BK4: =-EXP(-Parameters!B$42*'6states'!A4)*(-Parameters!B$37/Parameters!B$38/Parameters!E$25*(EXP(-Parameters!B$38*Parameters!E$25*'6states'!I4/('6states'!F4+'6states'!I4))-EXP(-Parameters!B$38*Parameters!E$25)) + Parameters!B$37*'6states'!F4/('6states'!F4+'6states'!I4)*EXP(-Parameters!B$38*Parameters!E$25*'6states'!I4/('6states'!F4+'6states'!I4))) -> -5.9757262 | BL4: =-J4*K4*EXP(-Parameters!B$42*'6states'!A4)*(-Parameters!B$37/Parameters!B$38/Parameters!E$25*(EXP(-Parameters!B$38*Parameters!E$25*'6states'!I4/('6states'!F4+'6states'!I4))-EXP(-Parameters!B$38*Parameters!E$25)) + Parameters!B$37*'6states'!F4/('6states'!F4+'6states'!I4)*EXP(-Parameters!B$38*Parameters!E$25*'6states'!I4/('6states'!F4+'6states'!I4))) -> -441.42162 | BM4: =I4/(F4+I4) -> 0 | BN4: =BK4-AU4 -> -6.8864 | BS4: =EXP(-Parameters!$B$56*A4)*BF4*BL4 -> 0.8131658 | BT4: =-EXP((Parameters!$B$56)*F4)*SUM(BS4:BS12) -> -1.1781449 | BU4: =$X4^-Parameters!$B$52/(1-2*Parameters!$B$5*'6states'!$D4/'6states'!$G4) -> 1.5456996 | BW4: =$X4^-Parameters!$B$52/(1-2*Parameters!$B$5*'6states'!$E4/'6states'!$H4) -> 0.87773378 | BY4: =($X4^-Parameters!$B$52*(1/(1+EXP(-C4)) + IF(C4<0,2*Parameters!$B$6*C4/F4,0)) + BQ4*(1/(1+EXP((C4-Parameters!$B$22)*Parameters!$B$21))))/(1-IF(C4>0,2*Parameters!$B$5*C4/F4,0)) -> 0.079902445 | CC4: =(Parameters!$B$18*'6states'!T4^+Parameters!$B$19*Parameters!$B$25^'6states'!T4)^((1-'6states'!T4)/'6states'!T4)*Parameters!$B$18*Parameters!$B$26^('6states'!T4-1) -> 0.12973347
A5: =A4+Parameters!$B$65 -> 1 | B5: 2026 | C5: -0.013294684 | D5: 0.041248303 | E5: 0.24555224 | F5: =MAX((1-Parameters!$B$4)^Parameters!B$65*F4 + C4*Parameters!B$65 - IF(C4>0,Parameters!$B$5,0)*C4^2/F4*Parameters!B$65, 0.0001) -> 0.71030048 | G5: =(1-Parameters!$B$4)^Parameters!B$65*G4+D4*Parameters!B$65-Parameters!$B$5*D4^2/G4*Parameters!B$65 -> 0.17146633 | H5: =(1-Parameters!$B$4)^Parameters!B$65*H4+E4*Parameters!B$65-Parameters!$B$5*E4^2/H4*Parameters!B$65 -> 4.3136679 | I5: =I4 *(1-Parameters!$B$4)-C4*(C4<0)*Parameters!B$65 -> 0.030791 | J5: =J4*(1+Parameters!$B$51)^Parameters!B$65 -> 8.183664 | K5: =K4*(1+Parameters!$B$53)^Parameters!B$65 -> 9.2336396 | L5: =J5*K5*EXP(-Parameters!$B$42*'6states'!A5)*(Parameters!$B$37/Parameters!$B$38*('6states'!F5+'6states'!I5)/Parameters!$E$25*(EXP(-Parameters!$B$38*Parameters!$E$25*'6states'!I5/('6states'!F5+'6states'!I5))-EXP(-Parameters!$B$38*Parameters!$E$25)) + Parameters!$B$39*'6states'!F5) -> 42.115043 | M5: =M4+L5*Parameters!B$65 -> 2342.115 | N5: =M5*Parameters!$B$45 -> 1.405269 | O5: =EXP(-Parameters!$B$46/2*N5^2) -> 0.9803491 | P5: =MAX((Parameters!$B$62 + Parameters!$B$31*'6states'!A5 - '6states'!M5 + Parameters!$B$47/Parameters!$B$45)/Parameters!B$62,1) -> 1.2216991 | Q5: =Parameters!B$61*EXP(-Parameters!B$60*A5) -> 0.48668062 | R5: =(1-Parameters!B$61)*P5^-Parameters!B$63 -> 0.49008745 | S5: =Parameters!B$61*EXP(-Parameters!B$60*A5)+(1-Parameters!B$61)*P5^-Parameters!B$63 -> 0.97676807 | T5: =1-S5/Parameters!$B$12 -> 0.51161597 | U5: =1/(1-T5) -> 2.047569 | V5: =(Parameters!$B$19*(F5+Parameters!$B$20)^T5+Parameters!$B$18*G5^T5)^(1/T5) -> 0.51461926 | W5: =(Parameters!$B$10*H5^Parameters!$B$9+Parameters!$B$11*V5^Parameters!$B$9)^(Parameters!$B$7/Parameters!$B$9)*O5 -> 1.4923874 | X5: =W5 - D5 - E5 - LN(1+EXP(Parameters!$B$21*C5))/Parameters!$B$21 - IF(C5>0, 0,Parameters!$B$6*C5^2/F5) -> 1.2042814 | Y5: =EXP(-Parameters!$B$55*A5) -> 0.98501343 | Z5: =IF(X5>0,X5^(1-Parameters!$B$52)/(1-Parameters!$B$52)*Y5*Parameters!$B$65,-10+X5*1000) -> -2.6370557 | AC5: =C5*$J5*$K5 -> -1.0046128 | AD5: =D5*$J5*$K5 -> 3.1169281 | AE5: =I5*J5*K5 -> 2.3267221 | AF5: =F5*J5*K5 -> 53.673859 | AG5: =G5*J5*K5 -> 12.956854 | AH5: =V5*J5*K5 -> 38.887207 | AI5: =AH5/AH$4*100 -> 95.704376 | AJ5: =W5*J5*K5 -> 112.77226 | AK5: =X5*J5*K5 -> 91.001532 | AL5: =LN(AJ5)-LN(AJ4) -> 0.016020359 | AM5: =LN(AK5)-LN(AK4) -> 0.020815248 | AQ5: =W5*K5*J5 -> 112.77226 | AR5: =Parameters!$B$7*W5*(W5/O5)^(-Parameters!$B$9/Parameters!$B$7)*Parameters!$B$11*(V5)^(Parameters!$B$9-T5)*((1-2*Parameters!$B$5*C5/F5)*Parameters!$B$19*(F5+Parameters!$B$20)^(T5-1)-(1-2*Parameters!$B$5*D5/G5)*(Parameters!$B$18)*(G5)^(T5-1)) -> 0.064700083 | AS5: =((C6-C4)/2-(F6-F4)/F5/2*C5)/(F5/2/Parameters!$B$5-C5)-((D6-D4)/D5-(G6-G4)/G5)/(G5/2/Parameters!$B$5/D5-1) -> 0.098586218 | AT5: =+Parameters!$B$5*C5^2/F5^2-Parameters!$B$5*D5^2/G5^2 -> -0.057519804 | AU5: =EXP(-Parameters!$B$42*'6states'!A5)*(Parameters!$B$37*EXP(-Parameters!$B$38*Parameters!$E$25*'6states'!I5/('6states'!F5+'6states'!I5))*(1/Parameters!$B$38/Parameters!$E$25+'6states'!I5/('6states'!F5+'6states'!I5))-Parameters!$B$37/Parameters!$B$38/Parameters!$E$25*EXP(-Parameters!$B$38*Parameters!$E$25)+Parameters!$B$39) -> 0.82649784 | AV5: =J5*K5*EXP(-Parameters!$B$42*'6states'!A5)*(Parameters!$B$37*EXP(-Parameters!$B$38*Parameters!$E$25*'6states'!I5/('6states'!F5+'6states'!I5))*(1/Parameters!$B$38/Parameters!$E$25+'6states'!I5/('6states'!F5+'6states'!I5))-Parameters!$B$37/Parameters!$B$38/Parameters!$E$25*EXP(-Parameters!$B$38*Parameters!$E$25)+Parameters!$B$39) -> 62.454313 | AW5: =1000*(AR5+AS5+AT5)/AU5 -> 127.96948 | AX5: =1-W5/'6states,ExoDamages'!T5 -> 0.006131762 | AY5: =-Y5*W5*X5^(-Parameters!B$52)*Parameters!B$46*Parameters!B$45*N5 -> -1.9384192e-05 | AZ5: =1000*EXP(-(Parameters!$B$54)*'6states'!A5)*AQ5*Parameters!B$46*Parameters!B$45*N5 -> 1.8452929 | BA5: =SUM(AZ5:AZ$204)*EXP(Parameters!$B$54*A5) -> 185.85283 | BB5: =((C5>0)*C5+D5+E5)/W5 -> 0.19217567 | BC5: =Parameters!$B$6*C5/F5 -> -0.093584928 | BD5: =Parameters!$B$5*D5/G5 -> 0.24056211 | BE5: =(1-2*BD5)/(1-2*BC5) -> 0.43706954 | BF5: =SUM(AY5:AY203)/Y5 -> -0.0018734178 | BG5: =BF5/Parameters!$B$45 -> -3.1223629 | BH5: =1-BG4/BG5 -> 0.016689052 | BI5: =-2*Parameters!B$6 * C5/F5*X5^-Parameters!B$52 -> 0.14563076 | BJ5: =X5^-Parameters!B$52 -> 0.77806738 | BK5: =-EXP(-Parameters!B$42*'6states'!A5)*(-Parameters!B$37/Parameters!B$38/Parameters!E$25*(EXP(-Parameters!B$38*Parameters!E$25*'6states'!AE5/('6states'!F5+'6states'!AE5))-EXP(-Parameters!B$38*Parameters!E$25))+Parameters!B$37*'6states'!F5/('6states'!F5+'6states'!AE5)*EXP(-Parameters!B$38*Parameters!E$25*'6states'!I5/('6states'!F5+'6states'!AE5))) -> -0.92012354 | BL5: =-J5*K5*EXP(-Parameters!B$42*'6states'!A5)*(-Parameters!B$37/Parameters!B$38/Parameters!E$25*(EXP(-Parameters!B$38*Parameters!E$25*'6states'!I5/('6states'!F5+'6states'!I5))-EXP(-Parameters!B$38*Parameters!E$25)) + Parameters!B$37*'6states'!F5/('6states'!F5+'6states'!I5)*EXP(-Parameters!B$38*Parameters!E$25*'6states'!I5/('6states'!F5+'6states'!I5))) -> -72.95266 | BM5: =I5/(F5+I5) -> 0.041548177 | BN5: =BK5-AU5 -> -1.7466214 | BS5: =EXP(-Parameters!$B$56*A5)*BF5*BL5 -> 0.12641564 | BT5: =-EXP((Parameters!$B$56)*F5)*SUM(BS5:BS13) -> -0.32245872 | BU5: =X5^-Parameters!B$52/(1-2*Parameters!B$5*'6states'!D5/'6states'!G5) -> 1.4995253 | BV5: =BU5/BU4 -> 0.97012728 | BW5: =$X5^-Parameters!$B$52/(1-2*Parameters!$B$5*'6states'!$E5/'6states'!$H5) -> 0.87802972 | BX5: =BW5/BW4 -> 1.0003372 | BY5: =($X5^-Parameters!$B$52*(1/(1+EXP(-C5)) + IF(C5<0,2*Parameters!$B$6*C5/F5,0)) + BQ5*(1/(1+EXP((C5-Parameters!$B$22)*Parameters!$B$21))))/(1-IF(C5>0,2*Parameters!$B$5*C5/F5,0)) -> 0.24081693 | BZ5: =BY5/BY4 -> 3.0138868 | CA5: =BY5-BY4 -> 0.16091448 | CB5: =(1/$T5-1/Parameters!$B$13) * LN(Parameters!$B$18) / LN(P5) -> 0.27014578 | CC5: =(Parameters!$B$18*'6states'!T5^+Parameters!$B$19*Parameters!$B$25^'6states'!T5)^((1-'6states'!T5)/'6states'!T5)*Parameters!$B$18*Parameters!$B$26^('6states'!T5-1) -> 0.13944009 | CD5: =(LN(CC5)-LN(CC$4))/ LN(P5) -> 0.36032768 | CE5: =1-2^-CB5 -> 0.17076425 | CF5: =1-2^-CC5 -> 0.092128568
A6: =A5+Parameters!$B$65 -> 2 | B6: 2027 | C6: -0.0085753021 | D6: 0.044268233 | E6: 0.24016693 | F6: =MAX((1-Parameters!$B$4)^Parameters!B$65*F5 + C5*Parameters!B$65 - IF(C5>0,Parameters!$B$5,0)*C5^2/F5*Parameters!B$65, 0.0001) -> 0.65232789 | G6: =(1-Parameters!$B$4)^Parameters!B$65*G5+D5*Parameters!B$65-Parameters!$B$5*D5^2/G5*Parameters!B$65 -> 0.19200662 | H6: =(1-Parameters!$B$4)^Parameters!B$65*H5+E5*Parameters!B$65-Parameters!$B$5*E5^2/H5*Parameters!B$65 -> 4.2739125 | I6: =I5 *(1-Parameters!$B$4)-C5*(C5<0)*Parameters!B$65 -> 0.04214893 | J6: =J5*(1+Parameters!$B$51)^Parameters!B$65 -> 8.2073966 | K6: =K5*(1+Parameters!$B$53)^Parameters!B$65 -> 9.4183124 | L6: =J6*K6*EXP(-Parameters!$B$42*'6states'!A6)*(Parameters!$B$37/Parameters!$B$38*('6states'!F6+'6states'!I6)/Parameters!$E$25*(EXP(-Parameters!$B$38*Parameters!$E$25*'6states'!I6/('6states'!F6+'6states'!I6))-EXP(-Parameters!$B$38*Parameters!$E$25)) + Parameters!$B$39*'6states'!F6) -> 38.479358 | M6: =M5+L6*Parameters!B$65 -> 2380.5944 | N6: =M6*Parameters!$B$45 -> 1.4283566 | O6: =EXP(-Parameters!$B$46/2*N6^2) -> 0.97970474 | P6: =MAX((Parameters!$B$62 + Parameters!$B$31*'6states'!A6 - '6states'!M6 + Parameters!$B$47/Parameters!$B$45)/Parameters!B$62,1) -> 1.516112 | Q6: =Parameters!B$61*EXP(-Parameters!B$60*A6) -> 0.47371605 | R6: =(1-Parameters!B$61)*P6^-Parameters!B$63 -> 0.47961955 | S6: =Parameters!B$61*EXP(-Parameters!B$60*A6)+(1-Parameters!B$61)*P6^-Parameters!B$63 -> 0.9533356 | T6: =1-S6/Parameters!$B$12 -> 0.5233322 | U6: =1/(1-T6) -> 2.0978971 | V6: =(Parameters!$B$19*(F6+Parameters!$B$20)^T6+Parameters!$B$18*G6^T6)^(1/T6) -> 0.49109712 | W6: =(Parameters!$B$10*H6^Parameters!$B$9+Parameters!$B$11*V6^Parameters!$B$9)^(Parameters!$B$7/Parameters!$B$9)*O6 -> 1.483427 | X6: =W6 - D6 - E6 - LN(1+EXP(Parameters!$B$21*C6))/Parameters!$B$21 - IF(C6>0, 0,Parameters!$B$6*C6^2/F6) -> 1.198183 | Y6: =EXP(-Parameters!$B$55*A6) -> 0.97025146 | Z6: =IF(X6>0,X6^(1-Parameters!$B$52)/(1-Parameters!$B$52)*Y6*Parameters!$B$65,-10+X6*1000) -> -2.602155 | AC6: =C6*$J6*$K6 -> -0.66286935 | AD6: =D6*$J6*$K6 -> 3.4219267 | AE6: =I6*J6*K6 -> 3.2581049 | AF6: =F6*J6*K6 -> 50.424832 | AG6: =G6*J6*K6 -> 14.842078 | AH6: =V6*J6*K6 -> 37.961722 | AI6: =AH6/AH$4*100 -> 93.426687 | AJ6: =W6*J6*K6 -> 114.66865 | AK6: =X6*J6*K6 -> 92.619338 | AL6: =LN(AJ6)-LN(AJ5) -> 0.016676307 | AM6: =LN(AK6)-LN(AK5) -> 0.017621611 | AQ6: =W6*K6*J6 -> 114.66865 | AR6: =Parameters!$B$7*W6*(W6/O6)^(-Parameters!$B$9/Parameters!$B$7)*Parameters!$B$11*(V6)^(Parameters!$B$9-T6)*((1-2*Parameters!$B$5*C6/F6)*Parameters!$B$19*(F6+Parameters!$B$20)^(T6-1)-(1-2*Parameters!$B$5*D6/G6)*(Parameters!$B$18)*(G6)^(T6-1)) -> 0.08009383 | AS6: =((C7-C5)/2-(F7-F5)/F6/2*C6)/(F6/2/Parameters!$B$5-C6)-((D7-D5)/D6-(G7-G5)/G6)/(G6/2/Parameters!$B$5/D6-1) -> 0.10710763 | AT6: =+Parameters!$B$5*C6^2/F6^2-Parameters!$B$5*D6^2/G6^2 -> -0.052983149 | AU6: =EXP(-Parameters!$B$42*'6states'!A6)*(Parameters!$B$37*EXP(-Parameters!$B$38*Parameters!$E$25*'6states'!I6/('6states'!F6+'6states'!I6))*(1/Parameters!$B$38/Parameters!$E$25+'6states'!I6/('6states'!F6+'6states'!I6))-Parameters!$B$37/Parameters!$B$38/Parameters!$E$25*EXP(-Parameters!$B$38*Parameters!$E$25)+Parameters!$B$39) -> 0.78987346 | AV6: =J6*K6*EXP(-Parameters!$B$42*'6states'!A6)*(Parameters!$B$37*EXP(-Parameters!$B$38*Parameters!$E$25*'6states'!I6/('6states'!F6+'6states'!I6))*(1/Parameters!$B$38/Parameters!$E$25+'6states'!I6/('6states'!F6+'6states'!I6))-Parameters!$B$37/Parameters!$B$38/Parameters!$E$25*EXP(-Parameters!$B$38*Parameters!$E$25)+Parameters!$B$39) -> 61.057081 | AW6: =1000*(AR6+AS6+AT6)/AU6 -> 169.92382 | AX6: =1-W6/'6states,ExoDamages'!T6 -> 0.011604402 | AY6: =-Y6*W6*X6^(-Parameters!B$52)*Parameters!B$46*Parameters!B$45*N6 -> -1.9423532e-05 | AZ6: =1000*EXP(-(Parameters!$B$54)*'6states'!A6)*AQ6*Parameters!B$46*Parameters!B$45*N6 -> 1.8413706 | BA6: =SUM(AZ6:AZ$204)*EXP(Parameters!$B$54*A6) -> 190.51261 | BB6: =((C6>0)*C6+D6+E6)/W6 -> 0.19174193 | BC6: =Parameters!$B$6*C6/F6 -> -0.065728464 | BD6: =Parameters!$B$5*D6/G6 -> 0.23055576 | BE6: =(1-2*BD6)/(1-2*BC6) -> 0.47627839 | BF6: =SUM(AY6:AY204)/Y6 -> -0.0018830942 | BG6: =BF6/Parameters!$B$45 -> -3.1384903 | BH6: =1-BG5/BG6 -> 0.0051385735 | BI6: =-2*Parameters!B$6 * C6/F6*X6^-Parameters!B$52 -> 0.10298577 | BJ6: =X6^-Parameters!B$52 -> 0.78341834 | BK6: =-EXP(-Parameters!B$42*'6states'!A6)*(-Parameters!B$37/Parameters!B$38/Parameters!E$25*(EXP(-Parameters!B$38*Parameters!E$25*'6states'!AE6/('6states'!F6+'6states'!AE6))-EXP(-Parameters!B$38*Parameters!E$25))+Parameters!B$37*'6states'!F6/('6states'!F6+'6states'!AE6)*EXP(-Parameters!B$38*Parameters!E$25*'6states'!I6/('6states'!F6+'6states'!AE6))) -> -0.63228458 | BL6: =-J6*K6*EXP(-Parameters!B$42*'6states'!A6)*(-Parameters!B$37/Parameters!B$38/Parameters!E$25*(EXP(-Parameters!B$38*Parameters!E$25*'6states'!I6/('6states'!F6+'6states'!I6))-EXP(-Parameters!B$38*Parameters!E$25)) + Parameters!B$37*'6states'!F6/('6states'!F6+'6states'!I6)*EXP(-Parameters!B$38*Parameters!E$25*'6states'!I6/('6states'!F6+'6states'!I6))) -> -32.026411 | BM6: =I6/(F6+I6) -> 0.060691629 | BN6: =BK6-AU6 -> -1.422158 | BS6: =EXP(-Parameters!$B$56*A6)*BF6*BL6 -> 0.051597704 | BT6: =-EXP((Parameters!$B$56)*F6)*SUM(BS6:BS14) -> -0.19933421 | BU6: =X6^-Parameters!B$52/(1-2*Parameters!B$5*'6states'!D6/'6states'!G6) -> 1.4537671 | BV6: =BU6/BU5 -> 0.96948484 | BW6: =$X6^-Parameters!$B$52/(1-2*Parameters!$B$5*'6states'!$E6/'6states'!$H6) -> 0.8826129 | BX6: =BW6/BW5 -> 1.0052198 | BY6: =($X6^-Parameters!$B$52 * (1/(1+EXP(-C6)) + IF(C6<0,2*Parameters!$B$6*C6/F6,0)) + BQ6 * (1/(1+EXP((C6-Parameters!$B$22)*Parameters!$B$21)))) / (1-IF(C6>0,2*Parameters!$B$5*C6/F6,0)) -> 0.2870439 | BZ6: =BY6/BY5 -> 1.191959 | CA6: =BY6-BY5 -> 0.046226971 | CB6: =(1/$T6-1/Parameters!$B$13) * LN(Parameters!$B$18) / LN(P6) -> 0.25525406 | CC6: =(Parameters!$B$18*'6states'!T6^+Parameters!$B$19*Parameters!$B$25^'6states'!T6)^((1-'6states'!T6)/'6states'!T6)*Parameters!$B$18*Parameters!$B$26^('6states'!T6-1) -> 0.14919534 | CD6: =(LN(CC6)-LN(CC$4))/ LN(P6) -> 0.3358756 | CE6: =1-2^-CB6 -> 0.16216042 | CF6: =1-2^-CC6 -> 0.098246724
A7: =A6+Parameters!$B$65 -> 3 | B7: 2028 | C7: 0.0053725717 | D7: 0.046844726 | E7: 0.23367109 | F7: =MAX((1-Parameters!$B$4)^Parameters!B$65*F6 + C6*Parameters!B$65 - IF(C6>0,Parameters!$B$5,0)*C6^2/F6*Parameters!B$65, 0.0001) -> 0.60272117 | G7: =(1-Parameters!$B$4)^Parameters!B$65*G6+D6*Parameters!B$65-Parameters!$B$5*D6^2/G6*Parameters!B$65 -> 0.21399134 | H7: =(1-Parameters!$B$4)^Parameters!B$65*H6+E6*Parameters!B$65-Parameters!$B$5*E6^2/H6*Parameters!B$65 -> 4.2317545 | I7: =I6 *(1-Parameters!$B$4)-C6*(C6<0)*Parameters!B$65 -> 0.048073064 | J7: =J6*(1+Parameters!$B$51)^Parameters!B$65 -> 8.2311981 | K7: =K6*(1+Parameters!$B$53)^Parameters!B$65 -> 9.6066786 | L7: =J7*K7*EXP(-Parameters!$B$42*'6states'!A7)*(Parameters!$B$37/Parameters!$B$38*('6states'!F7+'6states'!I7)/Parameters!$E$25*(EXP(-Parameters!$B$38*Parameters!$E$25*'6states'!I7/('6states'!F7+'6states'!I7))-EXP(-Parameters!$B$38*Parameters!$E$25)) + Parameters!$B$39*'6states'!F7) -> 35.78268 | M7: =M6+L7*Parameters!B$65 -> 2416.3771 | N7: =M7*Parameters!$B$45 -> 1.4498262 | O7: =EXP(-Parameters!$B$46/2*N7^2) -> 0.97909651 | P7: =MAX((Parameters!$B$62 + Parameters!$B$31*'6states'!A7 - '6states'!M7 + Parameters!$B$47/Parameters!$B$45)/Parameters!B$62,1) -> 1.8644584 | Q7: =Parameters!B$61*EXP(-Parameters!B$60*A7) -> 0.46109685 | R7: =(1-Parameters!B$61)*P7^-Parameters!B$63 -> 0.46980186 | S7: =Parameters!B$61*EXP(-Parameters!B$60*A7)+(1-Parameters!B$61)*P7^-Parameters!B$63 -> 0.93089871 | T7: =1-S7/Parameters!$B$12 -> 0.53455065 | U7: =1/(1-T7) -> 2.1484615 | V7: =(Parameters!$B$19*(F7+Parameters!$B$20)^T7+Parameters!$B$18*G7^T7)^(1/T7) -> 0.4714978 | W7: =(Parameters!$B$10*H7^Parameters!$B$9+Parameters!$B$11*V7^Parameters!$B$9)^(Parameters!$B$7/Parameters!$B$9)*O7 -> 1.4746259 | X7: =W7 - D7 - E7 - LN(1+EXP(Parameters!$B$21*C7))/Parameters!$B$21 - IF(C7>0, 0,Parameters!$B$6*C7^2/F7) -> 1.188131 | Y7: =EXP(-Parameters!$B$55*A7) -> 0.95571073 | Z7: =IF(X7>0,X7^(1-Parameters!$B$52)/(1-Parameters!$B$52)*Y7*Parameters!$B$65,-10+X7*1000) -> -2.5707266 | AC7: =C7*$J7*$K7 -> 0.42483329 | AD7: =D7*$J7*$K7 -> 3.7042221 | AE7: =I7*J7*K7 -> 3.8013523 | AF7: =F7*J7*K7 -> 47.65986 | AG7: =G7*J7*K7 -> 16.921253 | AH7: =V7*J7*K7 -> 37.283441 | AI7: =AH7/AH$4*100 -> 91.757388 | AJ7: =W7*J7*K7 -> 116.60526 | AK7: =X7*J7*K7 -> 93.950837 | AL7: =LN(AJ7)-LN(AJ6) -> 0.016747755 | AM7: =LN(AK7)-LN(AK6) -> 0.014273678 | AN7: =AVERAGE(AL5:AL9) -> 0.017107318 | AO7: =AVERAGE(AM5:AM9) -> 0.017396171 | AQ7: =W7*K7*J7 -> 116.60526 | AR7: =Parameters!$B$7*W7*(W7/O7)^(-Parameters!$B$9/Parameters!$B$7)*Parameters!$B$11*(V7)^(Parameters!$B$9-T7)*((1-2*Parameters!$B$5*C7/F7)*Parameters!$B$19*(F7+Parameters!$B$20)^(T7-1)-(1-2*Parameters!$B$5*D7/G7)*(Parameters!$B$18)*(G7)^(T7-1)) -> 0.089702438 | AS7: =((C8-C6)/2-(F8-F6)/F7/2*C7)/(F7/2/Parameters!$B$5-C7)-((D8-D6)/D7-(G8-G6)/G7)/(G7/2/Parameters!$B$5/D7-1) -> 0.10292869 | AT7: =+Parameters!$B$5*C7^2/F7^2-Parameters!$B$5*D7^2/G7^2 -> -0.047841888 | AU7: =EXP(-Parameters!$B$42*'6states'!A7)*(Parameters!$B$37*EXP(-Parameters!$B$38*Parameters!$E$25*'6states'!I7/('6states'!F7+'6states'!I7))*(1/Parameters!$B$38/Parameters!$E$25+'6states'!I7/('6states'!F7+'6states'!I7))-Parameters!$B$37/Parameters!$B$38/Parameters!$E$25*EXP(-Parameters!$B$38*Parameters!$E$25)+Parameters!$B$39) -> 0.76919088 | AV7: =J7*K7*EXP(-Parameters!$B$42*'6states'!A7)*(Parameters!$B$37*EXP(-Parameters!$B$38*Parameters!$E$25*'6states'!I7/('6states'!F7+'6states'!I7))*(1/Parameters!$B$38/Parameters!$E$25+'6states'!I7/('6states'!F7+'6states'!I7))-Parameters!$B$37/Parameters!$B$38/Parameters!$E$25*EXP(-Parameters!$B$38*Parameters!$E$25)+Parameters!$B$39) -> 60.823365 | AW7: =1000*(AR7+AS7+AT7)/AU7 -> 188.23577 | AX7: =1-W7/'6states,ExoDamages'!T7 -> 0.016993446 | AY7: =-Y7*W7*X7^(-Parameters!B$52)*Parameters!B$46*Parameters!B$45*N7 -> -1.9525615e-05 | AZ7: =1000*EXP(-(Parameters!$B$54)*'6states'!A7)*AQ7*Parameters!B$46*Parameters!B$45*N7 -> 1.8350598 | BA7: =SUM(AZ7:AZ$204)*EXP(Parameters!$B$54*A7) -> 195.2725 | BB7: =((C7>0)*C7+D7+E7)/W7 -> 0.19387181 | BF7: =SUM(AY7:AY205)/Y7 -> -0.001891421 | BG7: =BF7/Parameters!$B$45 -> -3.1523684 | BH7: =1-BG6/BG7 -> 0.0044024242 | BK7: =-EXP(-Parameters!B$42*'6states'!A7)*(-Parameters!B$37/Parameters!B$38/Parameters!E$25*(EXP(-Parameters!B$38*Parameters!E$25*'6states'!AE7/('6states'!F7+'6states'!AE7))-EXP(-Parameters!B$38*Parameters!E$25))+Parameters!B$37*'6states'!F7/('6states'!F7+'6states'!AE7)*EXP(-Parameters!B$38*Parameters!E$25*'6states'!I7/('6states'!F7+'6states'!AE7))) -> -0.51057135 | BL7: =-J7*K7*EXP(-Parameters!B$42*'6states'!A7)*(-Parameters!B$37/Parameters!B$38/Parameters!E$25*(EXP(-Parameters!B$38*Parameters!E$25*'6states'!I7/('6states'!F7+'6states'!I7))-EXP(-Parameters!B$38*Parameters!E$25)) + Parameters!B$37*'6states'!F7/('6states'!F7+'6states'!I7)*EXP(-Parameters!B$38*Parameters!E$25*'6states'!I7/('6states'!F7+'6states'!I7))) -> -18.239929 | BM7: =I7/(F7+I7) -> 0.073868301 | BN7: =BK7-AU7 -> -1.2797622 | BS7: =EXP(-Parameters!$B$56*A7)*BF7*BL7 -> 0.027301497 | BT7: =-EXP((Parameters!$B$56)*F7)*SUM(BS7:BS15) -> -0.15602895 | BU7: =X7^-Parameters!B$52/(1-2*Parameters!B$5*'6states'!D7/'6states'!G7) -> 1.4094734 | BV7: =BU7/BU6 -> 0.96953181 | BW7: =$X7^-Parameters!$B$52/(1-2*Parameters!$B$5*'6states'!$E7/'6states'!$H7) -> 0.89075122 | BX7: =BW7/BW6 -> 1.0092207 | BY7: =($X7^-Parameters!$B$52*(1/(1+EXP(-C7)) + IF(C7<0,2*Parameters!$B$6*C7/F7,0)) + BQ7*(1/(1+EXP((C7-Parameters!$B$22)*Parameters!$B$21))))/(1-IF(C7>0,2*Parameters!$B$5*C7/F7,0)) -> 0.40446463 | BZ7: =BY7/BY6 -> 1.4090689 | CA7: =BY7-BY6 -> 0.11742073 | CB7: =(1/$T7-1/Parameters!$B$13) * LN(Parameters!$B$18) / LN(P7) -> 0.24719701 | CC7: =(Parameters!$B$18*'6states'!T7^+Parameters!$B$19*Parameters!$B$25^'6states'!T7)^((1-'6states'!T7)/'6states'!T7)*Parameters!$B$18*Parameters!$B$26^('6states'!T7-1) -> 0.15845999 | CD7: =(LN(CC7)-LN(CC$4))/ LN(P7) -> 0.32107466 | CE7: =1-2^-CB7 -> 0.15746823 | CF7: =1-2^-CC7 -> 0.10401902
A8: =A7+Parameters!$B$65 -> 4 | B8: 2029 | C8: 0.006670523 | D8: 0.049576576 | E8: 0.2287485 | F8: =MAX((1-Parameters!$B$4)^Parameters!B$65*F7 + C7*Parameters!B$65 - IF(C7>0,Parameters!$B$5,0)*C7^2/F7*Parameters!B$65, 0.0001) -> 0.57013469 | G8: =(1-Parameters!$B$4)^Parameters!B$65*G7+D7*Parameters!B$65-Parameters!$B$5*D7^2/G7*Parameters!B$65 -> 0.23712126 | H8: =(1-Parameters!$B$4)^Parameters!B$65*H7+E7*Parameters!B$65-Parameters!$B$5*E7^2/H7*Parameters!B$65 -> 4.1863453 | I8: =I7 *(1-Parameters!$B$4)-C7*(C7<0)*Parameters!B$65 -> 0.045049269 | J8: =J7*(1+Parameters!$B$51)^Parameters!B$65 -> 8.2550686 | K8: =K7*(1+Parameters!$B$53)^Parameters!B$65 -> 9.7988122 | L8: =J8*K8*EXP(-Parameters!$B$42*'6states'!A8)*(Parameters!$B$37/Parameters!$B$38*('6states'!F8+'6states'!I8)/Parameters!$E$25*(EXP(-Parameters!$B$38*Parameters!$E$25*'6states'!I8/('6states'!F8+'6states'!I8))-EXP(-Parameters!$B$38*Parameters!$E$25)) + Parameters!$B$39*'6states'!F8) -> 34.288582 | M8: =M7+L8*Parameters!B$65 -> 2450.6657 | N8: =M8*Parameters!$B$45 -> 1.4703994 | O8: =EXP(-Parameters!$B$46/2*N8^2) -> 0.97850552 | P8: =MAX((Parameters!$B$62 + Parameters!$B$31*'6states'!A8 - '6states'!M8 + Parameters!$B$47/Parameters!$B$45)/Parameters!B$62,1) -> 2.2426867 | Q8: =Parameters!B$61*EXP(-Parameters!B$60*A8) -> 0.4488138 | R8: =(1-Parameters!B$61)*P8^-Parameters!B$63 -> 0.46120408 | S8: =Parameters!B$61*EXP(-Parameters!B$60*A8)+(1-Parameters!B$61)*P8^-Parameters!B$63 -> 0.91001788 | T8: =1-S8/Parameters!$B$12 -> 0.54499106 | U8: =1/(1-T8) -> 2.197759 | V8: =(Parameters!$B$19*(F8+Parameters!$B$20)^T8+Parameters!$B$18*G8^T8)^(1/T8) -> 0.46147468 | W8: =(Parameters!$B$10*H8^Parameters!$B$9+Parameters!$B$11*V8^Parameters!$B$9)^(Parameters!$B$7/Parameters!$B$9)*O8 -> 1.4676971 | X8: =W8 - D8 - E8 - LN(1+EXP(Parameters!$B$21*C8))/Parameters!$B$21 - IF(C8>0, 0,Parameters!$B$6*C8^2/F8) -> 1.1822789 | Y8: =EXP(-Parameters!$B$55*A8) -> 0.9413879 | Z8: =IF(X8>0,X8^(1-Parameters!$B$52)/(1-Parameters!$B$52)*Y8*Parameters!$B$65,-10+X8*1000) -> -2.5365802 | AC8: =C8*$J8*$K8 -> 0.53957772 | AD8: =D8*$J8*$K8 -> 4.0102426 | AE8: =I8*J8*K8 -> 3.6440293 | AF8: =F8*J8*K8 -> 46.118119 | AG8: =G8*J8*K8 -> 19.180707 | AH8: =V8*J8*K8 -> 37.328625 | AI8: =AH8/AH$4*100 -> 91.868589 | AJ8: =W8*J8*K8 -> 118.72182 | AK8: =X8*J8*K8 -> 95.63438 | AL8: =LN(AJ8)-LN(AJ7) -> 0.017988712 | AM8: =LN(AK8)-LN(AK7) -> 0.017760751 | AN8: =AVERAGE(AL6:AL10) -> 0.017309372 | AO8: =AVERAGE(AM6:AM10) -> 0.017174286 | AQ8: =W8*K8*J8 -> 118.72182 | AR8: =Parameters!$B$7*W8*(W8/O8)^(-Parameters!$B$9/Parameters!$B$7)*Parameters!$B$11*(V8)^(Parameters!$B$9-T8)*((1-2*Parameters!$B$5*C8/F8)*Parameters!$B$19*(F8+Parameters!$B$20)^(T8-1)-(1-2*Parameters!$B$5*D8/G8)*(Parameters!$B$18)*(G8)^(T8-1)) -> 0.097986481 | AS8: =((C9-C7)/2-(F9-F7)/F8/2*C8)/(F8/2/Parameters!$B$5-C8)-((D9-D7)/D8-(G9-G7)/G8)/(G8/2/Parameters!$B$5/D8-1) -> 0.05064868 | AT8: =+Parameters!$B$5*C8^2/F8^2-Parameters!$B$5*D8^2/G8^2 -> -0.043576259 | AU8: =EXP(-Parameters!$B$42*'6states'!A8)*(Parameters!$B$37*EXP(-Parameters!$B$38*Parameters!$E$25*'6states'!I8/('6states'!F8+'6states'!I8))*(1/Parameters!$B$38/Parameters!$E$25+'6states'!I8/('6states'!F8+'6states'!I8))-Parameters!$B$37/Parameters!$B$38/Parameters!$E$25*EXP(-Parameters!$B$38*Parameters!$E$25)+Parameters!$B$39) -> 0.76205092 | AV8: =J8*K8*EXP(-Parameters!$B$42*'6states'!A8)*(Parameters!$B$37*EXP(-Parameters!$B$38*Parameters!$E$25*'6states'!I8/('6states'!F8+'6states'!I8))*(1/Parameters!$B$38/Parameters!$E$25+'6states'!I8/('6states'!F8+'6states'!I8))-Parameters!$B$37/Parameters!$B$38/Parameters!$E$25*EXP(-Parameters!$B$38*Parameters!$E$25)+Parameters!$B$39) -> 61.642197 | AW8: =1000*(AR8+AS8+AT8)/AU8 -> 137.86336 | AX8: =1-W8/'6states,ExoDamages'!T8 -> 0.021138107 | AY8: =-Y8*W8*X8^(-Parameters!B$52)*Parameters!B$46*Parameters!B$45*N8 -> -1.9544104e-05 | AZ8: =1000*EXP(-(Parameters!$B$54)*'6states'!A8)*AQ8*Parameters!B$46*Parameters!B$45*N8 -> 1.8295245 | BA8: =SUM(AZ8:AZ$204)*EXP(Parameters!$B$54*A8) -> 200.13661 | BB8: =((C8>0)*C8+D8+E8)/W8 -> 0.19417876 | BF8: =SUM(AY8:AY206)/Y8 -> -0.0018994569 | BG8: =BF8/Parameters!$B$45 -> -3.1657615 | BH8: =1-BG7/BG8 -> 0.0042306157 | BK8: =-EXP(-Parameters!B$42*'6states'!A8)*(-Parameters!B$37/Parameters!B$38/Parameters!E$25*(EXP(-Parameters!B$38*Parameters!E$25*'6states'!AE8/('6states'!F8+'6states'!AE8))-EXP(-Parameters!B$38*Parameters!E$25))+Parameters!B$37*'6states'!F8/('6states'!F8+'6states'!AE8)*EXP(-Parameters!B$38*Parameters!E$25*'6states'!I8/('6states'!F8+'6states'!AE8))) -> -0.50453423 | BL8: =-J8*K8*EXP(-Parameters!B$42*'6states'!A8)*(-Parameters!B$37/Parameters!B$38/Parameters!E$25*(EXP(-Parameters!B$38*Parameters!E$25*'6states'!I8/('6states'!F8+'6states'!I8))-EXP(-Parameters!B$38*Parameters!E$25)) + Parameters!B$37*'6states'!F8/('6states'!F8+'6states'!I8)*EXP(-Parameters!B$38*Parameters!E$25*'6states'!I8/('6states'!F8+'6states'!I8))) -> -18.996373 | BM8: =I8/(F8+I8) -> 0.073228939 | BN8: =BK8-AU8 -> -1.2665851 | BS8: =EXP(-Parameters!$B$56*A8)*BF8*BL8 -> 0.026411937 | BT8: =-EXP((Parameters!$B$56)*F8)*SUM(BS8:BS16) -> -0.13886768 | BU8: =X8^-Parameters!B$52/(1-2*Parameters!B$5*'6states'!D8/'6states'!G8) -> 1.3709445 | BV8: =BU8/BU7 -> 0.97266432 | BW8: =$X8^-Parameters!$B$52/(1-2*Parameters!$B$5*'6states'!$E8/'6states'!$H8) -> 0.89554709 | BX8: =BW8/BW7 -> 1.0053841 | BY8: =($X8^-Parameters!$B$52*(1/(1+EXP(-C8)) + IF(C8<0,2*Parameters!$B$6*C8/F8,0)) + BQ8*(1/(1+EXP((C8-Parameters!$B$22)*Parameters!$B$21))))/(1-IF(C8>0,2*Parameters!$B$5*C8/F8,0)) -> 0.40975793 | BZ8: =BY8/BY7 -> 1.0130872 | CA8: =BY8-BY7 -> 0.0052933001 | CB8: =(1/$T8-1/Parameters!$B$13) * LN(Parameters!$B$18) / LN(P8) -> 0.24352519 | CC8: =(Parameters!$B$18*'6states'!T8^+Parameters!$B$19*Parameters!$B$25^'6states'!T8)^((1-'6states'!T8)/'6states'!T8)*Parameters!$B$18*Parameters!$B$26^('6states'!T8-1) -> 0.16698137 | CD8: =(LN(CC8)-LN(CC$4))/ LN(P8) -> 0.31250231 | CE8: =1-2^-CB8 -> 0.15532116 | CF8: =1-2^-CC8 -> 0.1092956
A9: =A8+Parameters!$B$65 -> 5 | B9: 2030 | C9: -0.0049074835 | D9: 0.052082521 | E9: 0.23299044 | F9: =MAX((1-Parameters!$B$4)^Parameters!B$65*F8 + C8*Parameters!B$65 - IF(C8>0,Parameters!$B$5,0)*C8^2/F8*Parameters!B$65, 0.0001) -> 0.54086569 | G9: =(1-Parameters!$B$4)^Parameters!B$65*G8+D8*Parameters!B$65-Parameters!$B$5*D8^2/G8*Parameters!B$65 -> 0.26141759 | H9: =(1-Parameters!$B$4)^Parameters!B$65*H8+E8*Parameters!B$65-Parameters!$B$5*E8^2/H8*Parameters!B$65 -> 4.1392735 | I9: =I8 *(1-Parameters!$B$4)-C8*(C8<0)*Parameters!B$65 -> 0.04221567 | J9: =J8*(1+Parameters!$B$51)^Parameters!B$65 -> 8.2790082 | K9: =K8*(1+Parameters!$B$53)^Parameters!B$65 -> 9.9947885 | L9: =J9*K9*EXP(-Parameters!$B$42*'6states'!A9)*(Parameters!$B$37/Parameters!$B$38*('6states'!F9+'6states'!I9)/Parameters!$E$25*(EXP(-Parameters!$B$38*Parameters!$E$25*'6states'!I9/('6states'!F9+'6states'!I9))-EXP(-Parameters!$B$38*Parameters!$E$25)) + Parameters!$B$39*'6states'!F9) -> 32.954207 | M9: =M8+L9*Parameters!B$65 -> 2483.6199 | N9: =M9*Parameters!$B$45 -> 1.4901719 | O9: =EXP(-Parameters!$B$46/2*N9^2) -> 0.97793003 | P9: =MAX((Parameters!$B$62 + Parameters!$B$31*'6states'!A9 - '6states'!M9 + Parameters!$B$47/Parameters!$B$45)/Parameters!B$62,1) -> 2.6476026 | Q9: =Parameters!B$61*EXP(-Parameters!B$60*A9) -> 0.43685796 | R9: =(1-Parameters!B$61)*P9^-Parameters!B$63 -> 0.4536122 | S9: =Parameters!B$61*EXP(-Parameters!B$60*A9)+(1-Parameters!B$61)*P9^-Parameters!B$63 -> 0.89047015 | T9: =1-S9/Parameters!$B$12 -> 0.55476492 | U9: =1/(1-T9) -> 2.2460045 | V9: =(Parameters!$B$19*(F9+Parameters!$B$20)^T9+Parameters!$B$18*G9^T9)^(1/T9) -> 0.45293778 | W9: =(Parameters!$B$10*H9^Parameters!$B$9+Parameters!$B$11*V9^Parameters!$B$9)^(Parameters!$B$7/Parameters!$B$9)*O9 -> 1.4609686 | X9: =W9 - D9 - E9 - LN(1+EXP(Parameters!$B$21*C9))/Parameters!$B$21 - IF(C9>0, 0,Parameters!$B$6*C9^2/F9) -> 1.1749845 | Y9: =EXP(-Parameters!$B$55*A9) -> 0.92727973 | Z9: =IF(X9>0,X9^(1-Parameters!$B$52)/(1-Parameters!$B$52)*Y9*Parameters!$B$65,-10+X9*1000) -> -2.5039836 | AC9: =C9*$J9*$K9 -> -0.40607923 | AD9: =D9*$J9*$K9 -> 4.3096691 | AE9: =I9*J9*K9 -> 3.4932173 | AF9: =F9*J9*K9 -> 44.754979 | AG9: =G9*J9*K9 -> 21.631505 | AH9: =V9*J9*K9 -> 37.479213 | AI9: =AH9/AH$4*100 -> 92.239197 | AJ9: =W9*J9*K9 -> 120.89067 | AK9: =X9*J9*K9 -> 97.226368 | AL9: =LN(AJ9)-LN(AJ8) -> 0.018103457 | AM9: =LN(AK9)-LN(AK8) -> 0.016509565 | AN9: =AVERAGE(AL7:AL11) -> 0.017329605 | AO9: =AVERAGE(AM7:AM11) -> 0.015952865 | AQ9: =W9*K9*J9 -> 120.89067 | AR9: =Parameters!$B$7*W9*(W9/O9)^(-Parameters!$B$9/Parameters!$B$7)*Parameters!$B$11*(V9)^(Parameters!$B$9-T9)*((1-2*Parameters!$B$5*C9/F9)*Parameters!$B$19*(F9+Parameters!$B$20)^(T9-1)-(1-2*Parameters!$B$5*D9/G9)*(Parameters!$B$18)*(G9)^(T9-1)) -> 0.11317706 | AS9: =((C10-C8)/2-(F10-F8)/F9/2*C9)/(F9/2/Parameters!$B$5-C9)-((D10-D8)/D9-(G10-G8)/G9)/(G9/2/Parameters!$B$5/D9-1) -> 0.040254691 | AT9: =+Parameters!$B$5*C9^2/F9^2-Parameters!$B$5*D9^2/G9^2 -> -0.039610715 | AU9: =EXP(-Parameters!$B$42*'6states'!A9)*(Parameters!$B$37*EXP(-Parameters!$B$38*Parameters!$E$25*'6states'!I9/('6states'!F9+'6states'!I9))*(1/Parameters!$B$38/Parameters!$E$25+'6states'!I9/('6states'!F9+'6states'!I9))-Parameters!$B$37/Parameters!$B$38/Parameters!$E$25*EXP(-Parameters!$B$38*Parameters!$E$25)+Parameters!$B$39) -> 0.75514101 | AV9: =J9*K9*EXP(-Parameters!$B$42*'6states'!A9)*(Parameters!$B$37*EXP(-Parameters!$B$38*Parameters!$E$25*'6states'!I9/('6states'!F9+'6states'!I9))*(1/Parameters!$B$38/Parameters!$E$25+'6states'!I9/('6states'!F9+'6states'!I9))-Parameters!$B$37/Parameters!$B$38/Parameters!$E$25*EXP(-Parameters!$B$38*Parameters!$E$25)+Parameters!$B$39) -> 62.485605 | AW9: =1000*(AR9+AS9+AT9)/AU9 -> 150.72819 | AX9: =1-W9/'6states,ExoDamages'!T9 -> 0.025150376 | AY9: =-Y9*W9*X9^(-Parameters!B$52)*Parameters!B$46*Parameters!B$45*N9 -> -1.9583573e-05 | AZ9: =1000*EXP(-(Parameters!$B$54)*'6states'!A9)*AQ9*Parameters!B$46*Parameters!B$45*N9 -> 1.8228788 | BA9: =SUM(AZ9:AZ$204)*EXP(Parameters!$B$54*A9) -> 205.10564 | BB9: =((C9>0)*C9+D9+E9)/W9 -> 0.19512601 | BF9: =SUM(AY9:AY207)/Y9 -> -0.0019072795 | BG9: =BF9/Parameters!$B$45 -> -3.1787992 | BH9: =1-BG8/BG9 -> 0.0041014569 | BK9: =-EXP(-Parameters!B$42*'6states'!A9)*(-Parameters!B$37/Parameters!B$38/Parameters!E$25*(EXP(-Parameters!B$38*Parameters!E$25*'6states'!AE9/('6states'!F9+'6states'!AE9))-EXP(-Parameters!B$38*Parameters!E$25))+Parameters!B$37*'6states'!F9/('6states'!F9+'6states'!AE9)*EXP(-Parameters!B$38*Parameters!E$25*'6states'!I9/('6states'!F9+'6states'!AE9))) -> -0.49979475 | BL9: =-J9*K9*EXP(-Parameters!B$42*'6states'!A9)*(-Parameters!B$37/Parameters!B$38/Parameters!E$25*(EXP(-Parameters!B$38*Parameters!E$25*'6states'!I9/('6states'!F9+'6states'!I9))-EXP(-Parameters!B$38*Parameters!E$25)) + Parameters!B$37*'6states'!F9/('6states'!F9+'6states'!I9)*EXP(-Parameters!B$38*Parameters!E$25*'6states'!I9/('6states'!F9+'6states'!I9))) -> -19.94787 | BM9: =I9/(F9+I9) -> 0.072400993 | BN9: =BK9-AU9 -> -1.2549358 | BS9: =EXP(-Parameters!$B$56*A9)*BF9*BL9 -> 0.025759417 | BT9: =-EXP((Parameters!$B$56)*F9)*SUM(BS9:BS17) -> -0.12303632 | BU9: =X9^-Parameters!B$52/(1-2*Parameters!B$5*'6states'!D9/'6states'!G9) -> 1.3371919 | BV9: =BU9/BU8 -> 0.97538 | BW9: =$X9^-Parameters!$B$52/(1-2*Parameters!$B$5*'6states'!$E9/'6states'!$H9) -> 0.90641109 | BX9: =BW9/BW8 -> 1.0121311 | BY9: =($X9^-Parameters!$B$52*(1/(1+EXP(-C9)) + IF(C9<0,2*Parameters!$B$6*C9/F9,0)) + BQ9*(1/(1+EXP((C9-Parameters!$B$22)*Parameters!$B$21))))/(1-IF(C9>0,2*Parameters!$B$5*C9/F9,0)) -> 0.32821511 | BZ9: =BY9/BY8 -> 0.80099758 | CA9: =BY9-BY8 -> -0.081542821 | CB9: =(1/$T9-1/Parameters!$B$13) * LN(Parameters!$B$18) / LN(P9) -> 0.24156391 | CC9: =(Parameters!$B$18*'6states'!T9^+Parameters!$B$19*Parameters!$B$25^'6states'!T9)^((1-'6states'!T9)/'6states'!T9)*Parameters!$B$18*Parameters!$B$26^('6states'!T9-1) -> 0.17484503 | CD9: =(LN(CC9)-LN(CC$4))/ LN(P9) -> 0.30649266 | CE9: =1-2^-CB9 -> 0.15417208 | CF9: =1-2^-CC9 -> 0.11413733
A10: =A9+Parameters!$B$65 -> 6 | B10: 2031 | C10: -0.004751195 | D10: 0.054566096 | E10: 0.22572886 | F10: =MAX((1-Parameters!$B$4)^Parameters!B$65*F9 + C9*Parameters!B$65 - IF(C9>0,Parameters!$B$5,0)*C9^2/F9*Parameters!B$65, 0.0001) -> 0.50193776 | G10: =(1-Parameters!$B$4)^Parameters!B$65*G9+D9*Parameters!B$65-Parameters!$B$5*D9^2/G9*Parameters!B$65 -> 0.28668049 | H10: =(1-Parameters!$B$4)^Parameters!B$65*H9+E9*Parameters!B$65-Parameters!$B$5*E9^2/H9*Parameters!B$65 -> 4.0987891 | I10: =I9 *(1-Parameters!$B$4)-C9*(C9<0)*Parameters!B$65 -> 0.044467788 | J10: =J9*(1+Parameters!$B$51)^Parameters!B$65 -> 8.3030174 | K10: =K9*(1+Parameters!$B$53)^Parameters!B$65 -> 10.194684 | L10: =J10*K10*EXP(-Parameters!$B$42*'6states'!A10)*(Parameters!$B$37/Parameters!$B$38*('6states'!F10+'6states'!I10)/Parameters!$E$25*(EXP(-Parameters!$B$38*Parameters!$E$25*'6states'!I10/('6states'!F10+'6states'!I10))-EXP(-Parameters!$B$38*Parameters!$E$25)) + Parameters!$B$39*'6states'!F10) -> 30.884858 | M10: =M9+L10*Parameters!B$65 -> 2514.5047 | N10: =M10*Parameters!$B$45 -> 1.5087028 | O10: =EXP(-Parameters!$B$46/2*N10^2) -> 0.97738401 | P10: =MAX((Parameters!$B$62 + Parameters!$B$31*'6states'!A10 - '6states'!M10 + Parameters!$B$47/Parameters!$B$45)/Parameters!B$62,1) -> 3.0939054 | Q10: =Parameters!B$61*EXP(-Parameters!B$60*A10) -> 0.4252206 | R10: =(1-Parameters!B$61)*P10^-Parameters!B$63 -> 0.4466006 | S10: =Parameters!B$61*EXP(-Parameters!B$60*A10)+(1-Parameters!B$61)*P10^-Parameters!B$63 -> 0.8718212 | T10: =1-S10/Parameters!$B$12 -> 0.5640894 | U10: =1/(1-T10) -> 2.2940484 | V10: =(Parameters!$B$19*(F10+Parameters!$B$20)^T10+Parameters!$B$18*G10^T10)^(1/T10) -> 0.43754904 | W10: =(Parameters!$B$10*H10^Parameters!$B$9+Parameters!$B$11*V10^Parameters!$B$9)^(Parameters!$B$7/Parameters!$B$9)*O10 -> 1.4527115 | X10: =W10 - D10 - E10 - LN(1+EXP(Parameters!$B$21*C10))/Parameters!$B$21 - IF(C10>0, 0,Parameters!$B$6*C10^2/F10) -> 1.1714735 | Y10: =EXP(-Parameters!$B$55*A10) -> 0.91338299 | Z10: =IF(X10>0,X10^(1-Parameters!$B$52)/(1-Parameters!$B$52)*Y10*Parameters!$B$65,-10+X10*1000) -> -2.4690422 | AC10: =C10*$J10*$K10 -> -0.40217269 | AD10: =D10*$J10*$K10 -> 4.6188367 | AE10: =I10*J10*K10 -> 3.7640488 | AF10: =F10*J10*K10 -> 42.487345 | AG10: =G10*J10*K10 -> 24.26654 | AH10: =V10*J10*K10 -> 37.037056 | AI10: =AH10/AH$4*100 -> 91.151015 | AJ10: =W10*J10*K10 -> 122.96715 | AK10: =X10*J10*K10 -> 99.161296 | AL10: =LN(AJ10)-LN(AJ9) -> 0.017030626 | AM10: =LN(AK10)-LN(AK9) -> 0.019705825 | AN10: =AVERAGE(AL8:AL12) -> 0.017739177 | AO10: =AVERAGE(AM8:AM12) -> 0.016756481 | AQ10: =W10*K10*J10 -> 122.96715 | AR10: =Parameters!$B$7*W10*(W10/O10)^(-Parameters!$B$9/Parameters!$B$7)*Parameters!$B$11*(V10)^(Parameters!$B$9-T10)*((1-2*Parameters!$B$5*C10/F10)*Parameters!$B$19*(F10+Parameters!$B$20)^(T10-1)-(1-2*Parameters!$B$5*D10/G10)*(Parameters!$B$18)*(G10)^(T10-1)) -> 0.13095282 | AS10: =((C11-C9)/2-(F11-F9)/F10/2*C10)/(F10/2/Parameters!$B$5-C10)-((D11-D9)/D10-(G11-G9)/G10)/(G10/2/Parameters!$B$5/D10-1) -> 0.099217782 | AT10: =+Parameters!$B$5*C10^2/F10^2-Parameters!$B$5*D10^2/G10^2 -> -0.03613883 | AU10: =EXP(-Parameters!$B$42*'6states'!A10)*(Parameters!$B$37*EXP(-Parameters!$B$38*Parameters!$E$25*'6states'!I10/('6states'!F10+'6states'!I10))*(1/Parameters!$B$38/Parameters!$E$25+'6states'!I10/('6states'!F10+'6states'!I10))-Parameters!$B$37/Parameters!$B$38/Parameters!$E$25*EXP(-Parameters!$B$38*Parameters!$E$25)+Parameters!$B$39) -> 0.74119965 | AV10: =J10*K10*EXP(-Parameters!$B$42*'6states'!A10)*(Parameters!$B$37*EXP(-Parameters!$B$38*Parameters!$E$25*'6states'!I10/('6states'!F10+'6states'!I10))*(1/Parameters!$B$38/Parameters!$E$25+'6states'!I10/('6states'!F10+'6states'!I10))-Parameters!$B$37/Parameters!$B$38/Parameters!$E$25*EXP(-Parameters!$B$38*Parameters!$E$25)+Parameters!$B$39) -> 62.74006 | AW10: =1000*(AR10+AS10+AT10)/AU10 -> 261.78072 | AX10: =1-W10/'6states,ExoDamages'!T10 -> 0.030196495 | AY10: =-Y10*W10*X10^(-Parameters!B$52)*Parameters!B$46*Parameters!B$45*N10 -> -1.9498198e-05 | AZ10: =1000*EXP(-(Parameters!$B$54)*'6states'!A10)*AQ10*Parameters!B$46*Parameters!B$45*N10 -> 1.8124987 | BA10: =SUM(AZ10:AZ$204)*EXP(Parameters!$B$54*A10) -> 210.18249 | BB10: =((C10>0)*C10+D10+E10)/W10 -> 0.19294606 | BF10: =SUM(AY10:AY208)/Y10 -> -0.0019148573 | BG10: =BF10/Parameters!$B$45 -> -3.1914288 | BH10: =1-BG9/BG10 -> 0.0039573478 | BK10: =-EXP(-Parameters!B$42*'6states'!A10)*(-Parameters!B$37/Parameters!B$38/Parameters!E$25*(EXP(-Parameters!B$38*Parameters!E$25*'6states'!AE10/('6states'!F10+'6states'!AE10))-EXP(-Parameters!B$38*Parameters!E$25))+Parameters!B$37*'6states'!F10/('6states'!F10+'6states'!AE10)*EXP(-Parameters!B$38*Parameters!E$25*'6states'!I10/('6states'!F10+'6states'!AE10))) -> -0.43500266 | BL10: =-J10*K10*EXP(-Parameters!B$42*'6states'!A10)*(-Parameters!B$37/Parameters!B$38/Parameters!E$25*(EXP(-Parameters!B$38*Parameters!E$25*'6states'!I10/('6states'!F10+'6states'!I10))-EXP(-Parameters!B$38*Parameters!E$25)) + Parameters!B$37*'6states'!F10/('6states'!F10+'6states'!I10)*EXP(-Parameters!B$38*Parameters!E$25*'6states'!I10/('6states'!F10+'6states'!I10))) -> -13.644647 | BM10: =I10/(F10+I10) -> 0.081382387 | BN10: =BK10-AU10 -> -1.1762023 | BS10: =EXP(-Parameters!$B$56*A10)*BF10*BL10 -> 0.016362471 | BT10: =-EXP((Parameters!$B$56)*F10)*SUM(BS10:BS18) -> -0.10817001 | BU10: =X10^-Parameters!B$52/(1-2*Parameters!B$5*'6states'!D10/'6states'!G10) -> 1.3040457 | BV10: =BU10/BU9 -> 0.97521208 | BW10: =$X10^-Parameters!$B$52/(1-2*Parameters!$B$5*'6states'!$E10/'6states'!$H10) -> 0.9075938 | BX10: =BW10/BW9 -> 1.0013048 | BY10: =($X10^-Parameters!$B$52*(1/(1+EXP(-C10)) + IF(C10<0,2*Parameters!$B$6*C10/F10,0)) + BQ10*(1/(1+EXP((C10-Parameters!$B$22)*Parameters!$B$21))))/(1-IF(C10>0,2*Parameters!$B$5*C10/F10,0)) -> 0.32640687 | BZ10: =BY10/BY9 -> 0.99449068 | CA10: =BY10-BY9 -> -0.001808243 | CB10: =(1/$T10-1/Parameters!$B$13) * LN(Parameters!$B$18) / LN(P10) -> 0.23967393 | CC10: =(Parameters!$B$18*'6states'!T10^+Parameters!$B$19*Parameters!$B$25^'6states'!T10)^((1-'6states'!T10)/'6states'!T10)*Parameters!$B$18*Parameters!$B$26^('6states'!T10-1) -> 0.18222472 | CD10: =(LN(CC10)-LN(CC$4))/ LN(P10) -> 0.30082194 | CE10: =1-2^-CB10 -> 0.15306329 | CF10: =1-2^-CC10 -> 0.11865714
A11: =A10+Parameters!$B$65 -> 7 | B11: 2032 | C11: 0.0094400994 | D11: 0.055426729 | E11: 0.22063307 | F11: =MAX((1-Parameters!$B$4)^Parameters!B$65*F10 + C10*Parameters!B$65 - IF(C10>0,Parameters!$B$5,0)*C10^2/F10*Parameters!B$65, 0.0001) -> 0.46561468 | G11: =(1-Parameters!$B$4)^Parameters!B$65*G10+D10*Parameters!B$65-Parameters!$B$5*D10^2/G10*Parameters!B$65 -> 0.3128284 | H11: =(1-Parameters!$B$4)^Parameters!B$65*H10+E10*Parameters!B$65-Parameters!$B$5*E10^2/H10*Parameters!B$65 -> 4.0542728 | I11: =I10 *(1-Parameters!$B$4)-C10*(C10<0)*Parameters!B$65 -> 0.046421959 | J11: =J10*(1+Parameters!$B$51)^Parameters!B$65 -> 8.3270961 | K11: =K10*(1+Parameters!$B$53)^Parameters!B$65 -> 10.398578 | L11: =J11*K11*EXP(-Parameters!$B$42*'6states'!A11)*(Parameters!$B$37/Parameters!$B$38*('6states'!F11+'6states'!I11)/Parameters!$E$25*(EXP(-Parameters!$B$38*Parameters!$E$25*'6states'!I11/('6states'!F11+'6states'!I11))-EXP(-Parameters!$B$38*Parameters!$E$25)) + Parameters!$B$39*'6states'!F11) -> 28.957266 | M11: =M10+L11*Parameters!B$65 -> 2543.462 | N11: =M11*Parameters!$B$45 -> 1.5260772 | O11: =EXP(-Parameters!$B$46/2*N11^2) -> 0.97686622 | P11: =MAX((Parameters!$B$62 + Parameters!$B$31*'6states'!A11 - '6states'!M11 + Parameters!$B$47/Parameters!$B$45)/Parameters!B$62,1) -> 3.5787601 | Q11: =Parameters!B$61*EXP(-Parameters!B$60*A11) -> 0.41389325 | R11: =(1-Parameters!B$61)*P11^-Parameters!B$63 -> 0.44014599 | S11: =Parameters!B$61*EXP(-Parameters!B$60*A11)+(1-Parameters!B$61)*P11^-Parameters!B$63 -> 0.85403924 | T11: =1-S11/Parameters!$B$12 -> 0.57298038 | U11: =1/(1-T11) -> 2.3418128 | V11: =(Parameters!$B$19*(F11+Parameters!$B$20)^T11+Parameters!$B$18*G11^T11)^(1/T11) -> 0.42309914 | W11: =(Parameters!$B$10*H11^Parameters!$B$9+Parameters!$B$11*V11^Parameters!$B$9)^(Parameters!$B$7/Parameters!$B$9)*O11 -> 1.4441355 | X11: =W11 - D11 - E11 - LN(1+EXP(Parameters!$B$21*C11))/Parameters!$B$21 - IF(C11>0, 0,Parameters!$B$6*C11^2/F11) -> 1.1584448 | Y11: =EXP(-Parameters!$B$55*A11) -> 0.89969452 | Z11: =IF(X11>0,X11^(1-Parameters!$B$52)/(1-Parameters!$B$52)*Y11*Parameters!$B$65,-10+X11*1000) -> -2.4415783 | AC11: =C11*$J11*$K11 -> 0.81741781 | AD11: =D11*$J11*$K11 -> 4.7993981 | AE11: =I11*J11*K11 -> 4.0196754 | AF11: =F11*J11*K11 -> 40.317555 | AG11: =G11*J11*K11 -> 27.087798 | AH11: =V11*J11*K11 -> 36.636137 | AI11: =AH11/AH$4*100 -> 90.164321 | AJ11: =W11*J11*K11 -> 125.04763 | AK11: =X11*J11*K11 -> 100.30969 | AL11: =LN(AJ11)-LN(AJ10) -> 0.016777473 | AM11: =LN(AK11)-LN(AK10) -> 0.011514508 | AN11: =AVERAGE(AL9:AL13) -> 0.017926911 | AO11: =AVERAGE(AM9:AM13) -> 0.016271371 | AQ11: =W11*K11*J11 -> 125.04763 | AR11: =Parameters!$B$7*W11*(W11/O11)^(-Parameters!$B$9/Parameters!$B$7)*Parameters!$B$11*(V11)^(Parameters!$B$9-T11)*((1-2*Parameters!$B$5*C11/F11)*Parameters!$B$19*(F11+Parameters!$B$20)^(T11-1)-(1-2*Parameters!$B$5*D11/G11)*(Parameters!$B$18)*(G11)^(T11-1)) -> 0.13543489 | AS11: =((C12-C10)/2-(F12-F10)/F11/2*C11)/(F11/2/Parameters!$B$5-C11)-((D12-D10)/D11-(G12-G10)/G11)/(G11/2/Parameters!$B$5/D11-1) -> 0.10223141 | AT11: =+Parameters!$B$5*C11^2/F11^2-Parameters!$B$5*D11^2/G11^2 -> -0.030981463 | AU11: =EXP(-Parameters!$B$42*'6states'!A11)*(Parameters!$B$37*EXP(-Parameters!$B$38*Parameters!$E$25*'6states'!I11/('6states'!F11+'6states'!I11))*(1/Parameters!$B$38/Parameters!$E$25+'6states'!I11/('6states'!F11+'6states'!I11))-Parameters!$B$37/Parameters!$B$38/Parameters!$E$25*EXP(-Parameters!$B$38*Parameters!$E$25)+Parameters!$B$39) -> 0.72883598 | AV11: =J11*K11*EXP(-Parameters!$B$42*'6states'!A11)*(Parameters!$B$37*EXP(-Parameters!$B$38*Parameters!$E$25*'6states'!I11/('6states'!F11+'6states'!I11))*(1/Parameters!$B$38/Parameters!$E$25+'6states'!I11/('6states'!F11+'6states'!I11))-Parameters!$B$37/Parameters!$B$38/Parameters!$E$25*EXP(-Parameters!$B$38*Parameters!$E$25)+Parameters!$B$39) -> 63.109877 | AW11: =1000*(AR11+AS11+AT11)/AU11 -> 283.58209 | AX11: =1-W11/'6states,ExoDamages'!T11 -> 0.035465733 | AY11: =-Y11*W11*X11^(-Parameters!B$52)*Parameters!B$46*Parameters!B$45*N11 -> -1.9606275e-05 | AZ11: =1000*EXP(-(Parameters!$B$54)*'6states'!A11)*AQ11*Parameters!B$46*Parameters!B$45*N11 -> 1.8000854 | BA11: =SUM(AZ11:AZ$204)*EXP(Parameters!$B$54*A11) -> 215.37359 | BB11: =((C11>0)*C11+D11+E11)/W11 -> 0.19769606 | BF11: =SUM(AY11:AY209)/Y11 -> -0.001922319 | BG11: =BF11/Parameters!$B$45 -> -3.203865 | BH11: =1-BG10/BG11 -> 0.0038816297 | BK11: =-EXP(-Parameters!B$42*'6states'!A11)*(-Parameters!B$37/Parameters!B$38/Parameters!E$25*(EXP(-Parameters!B$38*Parameters!E$25*'6states'!AE11/('6states'!F11+'6states'!AE11))-EXP(-Parameters!B$38*Parameters!E$25))+Parameters!B$37*'6states'!F11/('6states'!F11+'6states'!AE11)*EXP(-Parameters!B$38*Parameters!E$25*'6states'!I11/('6states'!F11+'6states'!AE11))) -> -0.3811737 | BL11: =-J11*K11*EXP(-Parameters!B$42*'6states'!A11)*(-Parameters!B$37/Parameters!B$38/Parameters!E$25*(EXP(-Parameters!B$38*Parameters!E$25*'6states'!I11/('6states'!F11+'6states'!I11))-EXP(-Parameters!B$38*Parameters!E$25)) + Parameters!B$37*'6states'!F11/('6states'!F11+'6states'!I11)*EXP(-Parameters!B$38*Parameters!E$25*'6states'!I11/('6states'!F11+'6states'!I11))) -> -9.2115753 | BM11: =I11/(F11+I11) -> 0.090661401 | BN11: =BK11-AU11 -> -1.1100097 | BS11: =EXP(-Parameters!$B$56*A11)*BF11*BL11 -> 0.010257336 | BT11: =-EXP((Parameters!$B$56)*F11)*SUM(BS11:BS19) -> -0.10345627 | BU11: =X11^-Parameters!B$52/(1-2*Parameters!B$5*'6states'!D11/'6states'!G11) -> 1.2699217 | BV11: =BU11/BU10 -> 0.97383226 | BW11: =$X11^-Parameters!$B$52/(1-2*Parameters!$B$5*'6states'!$E11/'6states'!$H11) -> 0.92005223 | BX11: =BW11/BW10 -> 1.0137269 | BY11: =($X11^-Parameters!$B$52*(1/(1+EXP(-C11)) + IF(C11<0,2*Parameters!$B$6*C11/F11,0)) + BQ11*(1/(1+EXP((C11-Parameters!$B$22)*Parameters!$B$21))))/(1-IF(C11>0,2*Parameters!$B$5*C11/F11,0)) -> 0.42929964 | BZ11: =BY11/BY10 -> 1.3152286 | CA11: =BY11-BY10 -> 0.10289277 | CB11: =(1/$T11-1/Parameters!$B$13) * LN(Parameters!$B$18) / LN(P11) -> 0.23800937 | CC11: =(Parameters!$B$18*'6states'!T11^+Parameters!$B$19*Parameters!$B$25^'6states'!T11)^((1-'6states'!T11)/'6states'!T11)*Parameters!$B$18*Parameters!$B$26^('6states'!T11-1) -> 0.18913427 | CD11: =(LN(CC11)-LN(CC$4))/ LN(P11) -> 0.29566294 | CE11: =1-2^-CB11 -> 0.15208554 | CF11: =1-2^-CC11 -> 0.12286809
