Workbook
Name ControlVars1to20: '6states'!$B$4:$D$24

Sheet Parameters
A2: Production and capital accumulation
A3: δ | B3: 0.04 | C3: decay rate of capital | M3: MAC
A4: δ+g_L+g | B4: =B3+B54+B52 -> 0.0629 | C4: decay rate of capital per unit of effective labour | L4: emissions | M4: Model | N4: MedianIPCC | O4: P25_IPCC | P4: P75_IPCC | Q4: MedianIPCC | R4: P25_IPCC | S4: P75_IPCC
A5: χ | B5: 1 | C5: investment adjustment cost | L5: -2.5 | M5: =_xlfn.XLOOKUP($L5,'6states'!$K$4:$K$104,'6states'!AS$4:AS$104,,-1) -> #N/A | N5: 830.6485 | O5: 534.3041 | P5: 1319.8 | Q5: 0.0282474 | R5: 0.0203494 | S5: 0.0396778
A6: χ_s | B6: 5 | C6: investment adjustment cost for negative investments | L6: 2.5 | M6: =_xlfn.XLOOKUP($L6,'6states'!$K$4:$K$104,'6states'!AS$4:AS$104,,-1) -> 954.8116 | N6: 606.6119 | O6: 387.1183 | P6: 1117.905 | Q6: 0.0266951 | R6: 0.0180696 | S6: 0.0408597
A7: α | B7: 0.3 | C7: share of capital income in national income | L7: 7.5 | M7: =_xlfn.XLOOKUP($L7,'6states'!$K$4:$K$104,'6states'!AS$4:AS$104,,-1) -> 491.5692 | N7: 417.0838 | O7: 242.3764 | P7: 684.3727 | Q7: 0.0196925 | R7: 0.0123111 | S7: 0.0283897
A8: σ_f | B8: 0.2 | C8: elasticity of substitution between energy and final capital | L8: 12.5 | M8: =_xlfn.XLOOKUP($L8,'6states'!$K$4:$K$101,'6states'!AS$4:AS$101,,-1) -> 352.25735 | N8: 369.451 | O8: 259.5315 | P8: 657.7192 | Q8: 0.0201464 | R8: 0.0142053 | S8: 0.0303724
A9: ε_f | B9: =1-1/B8 -> -4 | C9: 1-1/sigma | L9: 17.5 | M9: =_xlfn.XLOOKUP($L9,'6states'!$K$4:$K$101,'6states'!AS$4:AS$101,,-1) -> 287.34689 | N9: 279.1021 | O9: 194.9201 | P9: 471.1751 | Q9: 0.0194575 | R9: 0.0137847 | S9: 0.0288798
A10: φ_f | B10: =1-B11 -> 0.99994397 | C10: share parameter of final-good capital | L10: 22.5 | M10: =_xlfn.XLOOKUP($L10,'6states'!$K$4:$K$101,'6states'!AS$4:AS$101,,-1) -> 256.26342 | N10: 201.3134 | O10: 145.1962 | P10: 330 | Q10: 0.0183307 | R10: 0.0123982 | S10: 0.0285
A11: φ_E | B11: =1/(1+(B18*B16^B13+B19*B14^B13)^(B9/B13-1)*B18*B16^(B13-1)) -> 5.603267e-05 | C11: share parameter of energy capital, using Y_k_f=Y_k_c | L11: 27.5 | M11: =_xlfn.XLOOKUP($L11,'6states'!$K$4:$K$101,'6states'!AS$4:AS$101,,-1) -> 207.72092 | N11: 158.2803 | O11: 107.6669 | P11: 245.52 | Q11: 0.0160009 | R11: 0.0110032 | S11: 0.0237186
A12: σ[0] | B12: 2 | C12: elasticity of substitution between clean and dirty capital in energy sector (initially 2) | L12: 32.5 | M12: =_xlfn.XLOOKUP($L12,'6states'!$K$4:$K$101,'6states'!AS$4:AS$101,,-1) -> 193.43569 | N12: 112.6412 | O12: 81.44473 | P12: 177.918 | Q12: 0.0121626 | R12: 0.008787 | S12: 0.0173682
A13: ε[0] | B13: =1-1/B12 -> 0.5 | C13: 1-1/sigma | L13: 37.5 | M13: =_xlfn.XLOOKUP($L13,'6states'!$K$4:$K$101,'6states'!AS$4:AS$101,,-1) -> 184.39915 | N13: 89.53163 | O13: 58.81897 | P13: 159.2609 | Q13: 0.0082251 | R13: 0.0056994 | S13: 0.0138741
A14: θ_d | B14: 0.1841 | C14: ratio of dirty capital over final capital (k_d+xi)/k_f | L14: 42.5 | M14: =_xlfn.XLOOKUP($L14,'6states'!$K$4:$K$101,'6states'!AS$4:AS$101,,-1) -> 175.71981 | N14: 74.8676 | O14: 47.31793 | P14: 131.6824 | Q14: 0.006194 | R14: 0.0038782 | S14: 0.0092856
A15: k_c/(k_c+k_d+ξ) | B15: 0.16 | C15: ratio of renewable over all energy from IEA (should be 0.16) | L15: 47.5 | M15: =_xlfn.XLOOKUP($L15,'6states'!$K$4:$K$101,'6states'!AS$4:AS$101,,-1) -> 175.71981 | N15: 32.49194 | O15: 10.02872 | P15: 64.102 | Q15: 0.0027149 | R15: 0.0007531 | S15: 0.0051001
A16: θ_c | B16: =B14*B15/(1-B15) -> 0.035066667 | C16: ratio of renewable capital over final capital k_c/k_f | L16: 52.5 | M16: =_xlfn.XLOOKUP($L16,'6states'!$K$4:$K$101,'6states'!AS$4:AS$101,,-1) -> 175.71981 | N16: 1.7695 | O16: 0 | P16: 12.83052 | Q16: 0 | R16: 0 | S16: 0.0005013
A17: k_c/(k_d+ξ) | B17: =B16/B14 -> 0.19047619 | C17: ratio of renewable over clean energy | L17: 57.5 | M17: =_xlfn.XLOOKUP($L17,'6states'!$K$4:$K$101,'6states'!AS$4:AS$101,,-1) -> 171.50605 | N17: 2.24156 | O17: 0 | P17: 11.00962 | Q17: 0 | R17: 0 | S17: 1e-05
A18: φ_c | B18: =1-B19 -> 0.30383243 | C18: share parameter of clean capital | D18: =B18^(1/B13) -> 0.092314148
A19: φ_d | B19: =1/((B17)^(1-B13)+1) -> 0.69616757 | C19: share parameter of dirty capital | D19: =B18^(1/0.77) -> 0.21286109 | L19: Squared Error | M19: =SUMXMY2(M6:M16,N6:N16)/11/1000 -> 19.008207
A20: ξ | B20: 0.01 | C20: shift in the MAC curve (0.01) | L20: combined error | M20: =M19+#REF! -> #REF!
A21: varespilon | B21: 400 | C21: parameter in softplus function
A22: vareps2 | B22: 0 | C22: shift in softplus of stranding (0.004)
A24: Initial states
A25: k_d[0] | B25: =B27*B14-B20 -> 0.790835 | C25: initial dirty capital (ss in constantT&epsilon sheet) | D25: K_d[0] | E25: =B25*B$28*B$29 -> 58.418283 | F25: k_d[0] theory | G25: =B14*G27 -> 0.80194854 | H25: steady state capital return | I25: =(B57-B5*I26^2)/(1-2*B5*I26) -> 0.084904031
A26: k_c[0] | B26: =B27*B16 -> 0.15254 | C26: initial clean capital (ss in constantT&epsilon sheet) | D26: K_c[0] | E26: =B26*B$28*B$29 -> 11.267995 | F26: k_c[0] theory | G26: =B16*G27 -> 0.1527521 | H26: steady state i/k | I26: =(1-SQRT(1-4*B5*(B4)))/2/B5 -> 0.067449425
A27: k_f[0] | B27: 4.35 | C27: initial final capital (ss in constantT&epsilon sheet) | D27: K_f[0] | E27: =B27*B$28*B$29 -> 321.33066 | F27: k_f[0] theory | G27: =(B7*B10*(B10+B11*(B18*B16^B13+B19*B14^B13)^(B9/B13))^(B7/B9-1)*EXP(-B47/2*B48^2) / I25) ^ (1/(1-B7)) -> 4.3560486 | H27: steady state i/k, approximation | I27: =B4+B5*B4^2 -> 0.06685641
A28: L[0] | B28: 8.16 | C28: initial Labour | D28: K[0]=(k_f[0]+k_d[0]+k_c[0])*A[0]L[0] | E28: =(B25+B26+B27)*B28*B29 -> 391.01694 | F28: total capital
A29: A[0] | B29: =B30*EXP(B47/2*B48^2)/B28/(Parameters!$B$10*B27^Parameters!$B$9+B11*E30^Parameters!$B$9)^(Parameters!$B$7/Parameters!$B$9) -> 9.0525879 | C29: tfp (targeting Y0) | D29: k_ramsey | E29: =((Parameters!B3+Parameters!B51+Parameters!B53*Parameters!B54)/Parameters!B7)^(1/(Parameters!B7-1)) -> 6.8509746 | F29: k steady state in Ramsey model (without energy)k=((sigma+delta+etag)/alpha)^(1/alpha-1)
A30: Y[0] | B30: 110.98 | C30: initial GDP (trillion $, MERs) | D30: E[0] | E30: =(B18*B26^B13+B19*(B25+B20)^B13)^(1/B13) -> 0.55006251
A31: P_BAU | B31: 53.2 | C31: initial business as usual emissions | D31: k_c/(k_c+k_d) | E31: =B26/(B26+B25) -> 0.16169604 | F31: Slightly higher than in theory, due to effect of z
D32: Y_E*E/Y | E32: =B7*B11*E30^(B9-1)/(B10*B27^B9+B11*E30^B9) * E30 -> 0.05393028 | F32: share of energy capital in GDP
D33: Y_kf*kf/Y | E33: =B7*B10*B27^(B9-1)/(B10*B27^B9+B11*E30^B9) * B27 -> 0.24606972 | F33: share of final capital income in GDP
A35: Stranding costs
A36: A[0]L[0]ψ/(σ+g_ψ) | B36: =Parameters!B29*Parameters!B28*Parameters!B42/(Parameters!B3+B43) -> 1345.4134 | C36: cumulative stranded emissions per unit of stranded capital k_s at time zero
A37: Intercept | B37: 6.886 | C37: highest carbon intensity in GtCO2/T$, that is kg per $ (sum of a and c from calibration)
A38: ψ_1 | B38: =B37-B40 -> 6.119009
A39: ψ_2 | B39: 0.729 | C39: degrowth rate of psi as a function of cumulative stranded emissions (calibrated parameter per Billion $ multiplied by 1000)
A40: ψ_3 | B40: =(B31-B37/B39*(1-EXP(-B39*E25)))/(E25-(1-EXP(-B39*E25))/B39) -> 0.76699101
A41: ψ_min | B41: =B38*EXP(-B39*E25)+B40 -> 0.76699101 | C41: lowest emissions intensity of capital at start
A42: \bar{ψ} | B42: =B31/B28/B29/B25 -> 0.9106738 | C42: mean emissions intensity at start
A43: g_ψ | B43: 0.01 | C43: autonomous decrease in carbon intensity
...

Sheet 6states
A1: 6 states: k_f, k_d, k_c, k_s, T, time
I2: =8.6*12 -> 103.2
A3: Period | B3: i_d[t] | C3: i_c[t] | D3: i_f[t] | E3: k_d[t] | F3: k_c[t] | G3: k_f[t] | H3: k_s[t] | I3: L[t] | J3: A[t] | K3: P[t] | L3: S[t] | M3: T[t] | N3: Ω[t] | O3: M[t]/M[0] | P3: ω*exp(g_σ)*t | Q3: ω*M[t]^-ρ | R3: TC[t] | S3: ε[t] | T3: σ[t] | U3: E[t]/(A[t]*L[t]) | V3: y[t] | W3: c[t] | X3: β^t | Y3: β^t * u(c[t]) | Z3: W | AA3: FD id/kd | AB3: FD ic/kc | AC3: FD if/kf | AD3: Discounted sum of FDs | AE3: SD id/kd | AF3: SD ic/kc | AG3: SD if/kf | AH3: Discounted sum of SDs | AJ3: W w/ penalty | AM3: K_s[t] | AN3: K_d[t] | AO3: E[t] | AP3: Y[t] | AQ3: Mgl damage[t] (utils) | AR3: Mgl damage[t] ($) | AS3: SCC[t] | AT3: s[t] | AU3: elasticity wrt M for LT clean productivity | AV3: E_kc at initial capital ratios | AW3: LR elasticity wrt M for initial clean productivity | AX3: Learning rate | AY3: Learning rate at initial k_j
A4: 0 | B4: -0.028124507 | C4: 0.036740613 | D4: 0.25584329 | E4: =Parameters!B25 -> 0.790835 | F4: =Parameters!B26 -> 0.15254 | G4: =Parameters!B27 -> 4.35 | H4: 0 | I4: =Parameters!B28 -> 8.16 | J4: =Parameters!B29 -> 9.0525879 | K4: =I4*J4*EXP(-Parameters!$B$43*'6states'!A4)*(Parameters!$B$38/Parameters!$B$39*('6states'!E4+'6states'!H4)/Parameters!$E$25*(EXP(-Parameters!$B$39*Parameters!$E$25*'6states'!H4/('6states'!E4+'6states'!H4))-EXP(-Parameters!$B$39*Parameters!$E$25)) + Parameters!$B$40*'6states'!E4) -> 53.2 | L4: =M4/Parameters!$B$46 -> 2300 | M4: =Parameters!B48 -> 1.38 | N4: =EXP(-Parameters!$B$47/2*M4^2) -> 0.98104277 | O4: =MAX((Parameters!$B$63 + Parameters!$B$31*'6states'!A4 - '6states'!L4 + Parameters!$B$48/Parameters!$B$46)/Parameters!B$63,1) -> 1 | P4: =Parameters!B$62*EXP(-Parameters!B$61*A4) -> 0.5 | Q4: =(1-Parameters!B$62)*O4^-Parameters!B$64 -> 0.5 | R4: =Parameters!B$62*EXP(-Parameters!B$61*A4)+(1-Parameters!B$62)*O4^-Parameters!B$64 -> 1 | S4: =1-R4/Parameters!$B$12 -> 0.5 | T4: =1/(1-S4) -> 2 | U4: =(Parameters!$B$19*(E4+Parameters!$B$20)^S4+Parameters!$B$18*F4^S4)^(1/S4) -> 0.55006251 | V4: =(Parameters!$B$10*G4^Parameters!$B$9+Parameters!$B$11*U4^Parameters!$B$9)^(Parameters!$B$7/Parameters!$B$9)*N4 -> 1.502387 | W4: =V4 - C4 - D4 - LN(1+EXP(Parameters!$B$21*B4))/Parameters!$B$21 - IF(B4>0, 0,Parameters!$B$6*B4^2/E4) -> 1.2048021 | X4: =EXP(-Parameters!$B$56*A4) -> 1 | Y4: =IF(W4>0,W4^(1-Parameters!$B$53)/(1-Parameters!$B$53)*X4*Parameters!$B$71,-10+W4*1000) -> -2.6767725 | Z4: =SUM(Y4:Y204)*Parameters!$B$71 -> -186.87944 | AJ4: =Z4-AK7*SUM(AD5:AD204)-AK8*SUM(AH5:AH204) -> -186.88602 | AM4: =H4*I4*J4 -> 0 | AN4: =E4*I4*J4 -> 58.418283 | AO4: =U4*I4*J4 -> 40.632632 | AP4: =V4*J4*I4 -> 110.98 | AR4: =1000*EXP(-(Parameters!$B$55)*'6states'!A4)*AP4*Parameters!B$47*Parameters!B$46*M4 -> 1.8470179 | AS4: =SUM(AR4:AR$204)*EXP(Parameters!$B$55*A4) -> 171.50605 | AT4: =((B4>0)*B4+C4+D4)/V4 -> 0.19474603 | AV4: =(Parameters!$B$18*'6states'!S4^+Parameters!$B$19*Parameters!$B$25^'6states'!S4)^((1-'6states'!S4)/'6states'!S4)*Parameters!$B$18*Parameters!$B$26^('6states'!S4-1) -> 0.12973347
A5: =A4+Parameters!$B$71 -> 1 | B5: -0.01049962 | C5: 0.040543532 | D5: 0.25057863 | E5: =MAX((1-Parameters!$B$4)^Parameters!B$71*E4 + B4*Parameters!B$71 - IF(B4>0,Parameters!$B$5,0)*B4^2/E4*Parameters!B$71, 0.0001) -> 0.71296697 | F5: =(1-Parameters!$B$4)^Parameters!B$71*F4+C4*Parameters!B$71-Parameters!$B$5*C4^2/F4*Parameters!B$71 -> 0.17083654 | G5: =(1-Parameters!$B$4)^Parameters!B$71*G4+D4*Parameters!B$71-Parameters!$B$5*D4^2/G4*Parameters!B$71 -> 4.317181 | H5: =MAX(H4 * (1-Parameters!$B$4) ^ Parameters!B$71 + (LN(1+EXP(Parameters!$B$21*(-B4+0.004)))/Parameters!$B$21 -0.004) * Parameters!B$71,0) -> 0.028124513 | I5: =I4*(1+Parameters!$B$52)^Parameters!B$71 -> 8.183664 | J5: =J4*(1+Parameters!$B$54)^Parameters!B$71 -> 9.2336396 | K5: =I5*J5*EXP(-Parameters!$B$43*'6states'!A5)*(Parameters!$B$38/Parameters!$B$39*('6states'!E5+'6states'!H5)/Parameters!$E$25*(EXP(-Parameters!$B$39*Parameters!$E$25*'6states'!H5/('6states'!E5+'6states'!H5))-EXP(-Parameters!$B$39*Parameters!$E$25)) + Parameters!$B$40*'6states'!E5) -> 42.493298 | L5: =L4+K5*Parameters!B$71 -> 2342.4933 | M5: =L5*Parameters!$B$46 -> 1.405496 | N5: =EXP(-Parameters!$B$47/2*M5^2) -> 0.98034281 | O5: =MAX((Parameters!$B$63 + Parameters!$B$31*'6states'!A5 - '6states'!L5 + Parameters!$B$48/Parameters!$B$46)/Parameters!B$63,1) -> 1.214134 | P5: =Parameters!B$62*EXP(-Parameters!B$61*A5) -> 0.48668062 | Q5: =(1-Parameters!B$62)*O5^-Parameters!B$64 -> 0.49039196 | R5: =Parameters!B$62*EXP(-Parameters!B$61*A5)+(1-Parameters!B$62)*O5^-Parameters!B$64 -> 0.97707258 | S5: =1-R5/Parameters!$B$12 -> 0.51146371 | T5: =1/(1-S5) -> 2.0469308 | U5: =(Parameters!$B$19*(E5+Parameters!$B$20)^S5+Parameters!$B$18*F5^S5)^(1/S5) -> 0.51585261 | V5: =(Parameters!$B$10*G5^Parameters!$B$9+Parameters!$B$11*U5^Parameters!$B$9)^(Parameters!$B$7/Parameters!$B$9)*N5 -> 1.4928952 | W5: =V5 - C5 - D5 - LN(1+EXP(Parameters!$B$21*B5))/Parameters!$B$21 - IF(B5>0, 0,Parameters!$B$6*B5^2/E5) -> 1.2009627 | X5: =EXP(-Parameters!$B$56*A5) -> 0.98501343 | Y5: =IF(W5>0,W5^(1-Parameters!$B$53)/(1-Parameters!$B$53)*X5*Parameters!$B$71,-10+W5*1000) -> -2.639604 | AB5: =C5/F5-C4/F4 -> -0.0035353471 | AC5: =D5/G5-D4/G4 -> -0.0007723626 | AD5: =X5*(AA5^2+AB5^2+AC5^2) -> 1.2898971e-05 | AH5: =X5*(AE5^2+AF5^2+AG5^2) -> 0 | AM5: =H5*I5*J5 -> 2.1252289 | AN5: =E5*I5*J5 -> 53.875352 | AO5: =U5*I5*J5 -> 38.980405 | AP5: =V5*J5*I5 -> 112.81063 | AQ5: =-X5*V5*W5^(-Parameters!B$53)*Parameters!B$47*Parameters!B$46*M5 -> -1.9466305e-05 | AR5: =1000*EXP(-(Parameters!$B$55)*'6states'!A5)*AP5*Parameters!B$47*Parameters!B$46*M5 -> 1.846219 | AS5: =SUM(AR5:AR$204)*EXP(Parameters!$B$55*A5) -> 175.71981 | AT5: =((B5>0)*B5+C5+D5)/V5 -> 0.19500508 | AU5: =(1/$S5-1/Parameters!$B$13) * LN(Parameters!$B$18) / LN(O5) -> 0.27522157 | AV5: =(Parameters!$B$18*'6states'!S5^+Parameters!$B$19*Parameters!$B$25^'6states'!S5)^((1-'6states'!S5)/'6states'!S5)*Parameters!$B$18*Parameters!$B$26^('6states'!S5-1) -> 0.13931298 | AW5: =(LN(AV5)-LN(AV$4))/ LN(O5) -> 0.36716267 | AX5: =1-2^-AU5 -> 0.1736766 | AY5: =1-2^-AV5 -> 0.092048576 | AZ5: =(1/$S5-1/Parameters!$B$13) * LN(Parameters!$B$18) / A5 -> 0.053401545
A6: =A5+Parameters!$B$71 -> 2 | B6: -0.0066558129 | C6: 0.044251293 | D6: 0.24474072 | E6: =MAX((1-Parameters!$B$4)^Parameters!B$71*E5 + B5*Parameters!B$71 - IF(B5>0,Parameters!$B$5,0)*B5^2/E5*Parameters!B$71, 0.0001) -> 0.65762173 | F6: =(1-Parameters!$B$4)^Parameters!B$71*F5+C5*Parameters!B$71-Parameters!$B$5*C5^2/F5*Parameters!B$71 -> 0.19101252 | G6: =(1-Parameters!$B$4)^Parameters!B$71*G5+D5*Parameters!B$71-Parameters!$B$5*D5^2/G5*Parameters!B$71 -> 4.2816648 | H6: =MAX(H5 * (1-Parameters!$B$4) ^ Parameters!B$71 + (LN(1+EXP(Parameters!$B$21*(-B5+0.004)))/Parameters!$B$21 -0.004) * Parameters!B$71,0) -> 0.03686266 | I6: =I5*(1+Parameters!$B$52)^Parameters!B$71 -> 8.2073966 | J6: =J5*(1+Parameters!$B$54)^Parameters!B$71 -> 9.4183124 | K6: =I6*J6*EXP(-Parameters!$B$43*'6states'!A6)*(Parameters!$B$38/Parameters!$B$39*('6states'!E6+'6states'!H6)/Parameters!$E$25*(EXP(-Parameters!$B$39*Parameters!$E$25*'6states'!H6/('6states'!E6+'6states'!H6))-EXP(-Parameters!$B$39*Parameters!$E$25)) + Parameters!$B$40*'6states'!E6) -> 39.005797 | L6: =L5+K6*Parameters!B$71 -> 2381.4991 | M6: =L6*Parameters!$B$46 -> 1.4288995 | N6: =EXP(-Parameters!$B$47/2*M6^2) -> 0.97968947 | O6: =MAX((Parameters!$B$63 + Parameters!$B$31*'6states'!A6 - '6states'!L6 + Parameters!$B$48/Parameters!$B$46)/Parameters!B$63,1) -> 1.4980181 | P6: =Parameters!B$62*EXP(-Parameters!B$61*A6) -> 0.47371605 | Q6: =(1-Parameters!B$62)*O6^-Parameters!B$64 -> 0.48019573 | R6: =Parameters!B$62*EXP(-Parameters!B$61*A6)+(1-Parameters!B$62)*O6^-Parameters!B$64 -> 0.95391179 | S6: =1-R6/Parameters!$B$12 -> 0.52304411 | T6: =1/(1-S6) -> 2.0966299 | U6: =(Parameters!$B$19*(E6+Parameters!$B$20)^S6+Parameters!$B$18*F6^S6)^(1/S6) -> 0.49379805 | V6: =(Parameters!$B$10*G6^Parameters!$B$9+Parameters!$B$11*U6^Parameters!$B$9)^(Parameters!$B$7/Parameters!$B$9)*N6 -> 1.4846062 | W6: =V6 - C6 - D6 - LN(1+EXP(Parameters!$B$21*B6))/Parameters!$B$21 - IF(B6>0, 0,Parameters!$B$6*B6^2/E6) -> 1.1951087 | X6: =EXP(-Parameters!$B$56*A6) -> 0.97025146 | Y6: =IF(W6>0,W6^(1-Parameters!$B$53)/(1-Parameters!$B$53)*X6*Parameters!$B$71,-10+W6*1000) -> -2.6044958 | AB6: =C6/F6-C5/F5 -> -0.0056565586 | AC6: =D6/G6-D5/G5 -> -0.00088201029 | AD6: =X6*(AA6^2+AB6^2+AC6^2) -> 3.1799602e-05 | AF6: =C6/F6-2*C5/F5+C4/F4 -> -0.0021212115 | AG6: =D6/G6-2*D5/G5+D4/G4 -> -0.0001096477 | AH6: =X6*(AE6^2+AF6^2+AG6^2) -> 4.3773487e-06 | AJ6: Penalty weights | AM6: =H6*I6*J6 -> 2.8494772 | AN6: =E6*I6*J6 -> 50.834045 | AO6: =U6*I6*J6 -> 38.170503 | AP6: =V6*J6*I6 -> 114.7598 | AQ6: =-X6*V6*W6^(-Parameters!B$53)*Parameters!B$47*Parameters!B$46*M6 -> -1.9513921e-05 | AR6: =1000*EXP(-(Parameters!$B$55)*'6states'!A6)*AP6*Parameters!B$47*Parameters!B$46*M6 -> 1.8435346 | AS6: =SUM(AR6:AR$204)*EXP(Parameters!$B$55*A6) -> 180.01661 | AT6: =((B6>0)*B6+C6+D6)/V6 -> 0.19465903 | AU6: =(1/$S6-1/Parameters!$B$13) * LN(Parameters!$B$18) / LN(O6) -> 0.2597347 | AV6: =(Parameters!$B$18*'6states'!S6^+Parameters!$B$19*Parameters!$B$25^'6states'!S6)^((1-'6states'!S6)/'6states'!S6)*Parameters!$B$18*Parameters!$B$26^('6states'!S6-1) -> 0.14895626 | AW6: =(LN(AV6)-LN(AV$4))/ LN(O6) -> 0.3418855 | AX6: =1-2^-AU6 -> 0.1647585 | AY6: =1-2^-AV6 -> 0.098097277 | AZ6: =(1/$S6-1/Parameters!$B$13) * LN(Parameters!$B$18) / A6 -> 0.052484977
A7: =A6+Parameters!$B$71 -> 3 | B7: -0.0048907717 | C7: 0.047731894 | D7: 0.23983585 | E7: =MAX((1-Parameters!$B$4)^Parameters!B$71*E6 + B6*Parameters!B$71 - IF(B6>0,Parameters!$B$5,0)*B6^2/E6*Parameters!B$71, 0.0001) -> 0.60960151 | F7: =(1-Parameters!$B$4)^Parameters!B$71*F6+C6*Parameters!B$71-Parameters!$B$5*C6^2/F6*Parameters!B$71 -> 0.21299757 | G7: =(1-Parameters!$B$4)^Parameters!B$71*G6+D6*Parameters!B$71-Parameters!$B$5*D6^2/G6*Parameters!B$71 -> 4.2430994 | H7: =MAX(H6 * (1-Parameters!$B$4) ^ Parameters!B$71 + (LN(1+EXP(Parameters!$B$21*(-B6+0.004)))/Parameters!$B$21 -0.004) * Parameters!B$71,0) -> 0.041234789 | I7: =I6*(1+Parameters!$B$52)^Parameters!B$71 -> 8.2311981 | J7: =J6*(1+Parameters!$B$54)^Parameters!B$71 -> 9.6066786 | K7: =I7*J7*EXP(-Parameters!$B$43*'6states'!A7)*(Parameters!$B$38/Parameters!$B$39*('6states'!E7+'6states'!H7)/Parameters!$E$25*(EXP(-Parameters!$B$39*Parameters!$E$25*'6states'!H7/('6states'!E7+'6states'!H7))-EXP(-Parameters!$B$39*Parameters!$E$25)) + Parameters!$B$40*'6states'!E7) -> 36.36244 | L7: =L6+K7*Parameters!B$71 -> 2417.8615 | M7: =L7*Parameters!$B$46 -> 1.4507169 | N7: =EXP(-Parameters!$B$47/2*M7^2) -> 0.97907109 | O7: =MAX((Parameters!$B$63 + Parameters!$B$31*'6states'!A7 - '6states'!L7 + Parameters!$B$48/Parameters!$B$46)/Parameters!B$63,1) -> 1.8347693 | P7: =Parameters!B$62*EXP(-Parameters!B$61*A7) -> 0.46109685 | Q7: =(1-Parameters!B$62)*O7^-Parameters!B$64 -> 0.47055659 | R7: =Parameters!B$62*EXP(-Parameters!B$61*A7)+(1-Parameters!B$62)*O7^-Parameters!B$64 -> 0.93165343 | S7: =1-R7/Parameters!$B$12 -> 0.53417328 | T7: =1/(1-S7) -> 2.146721 | U7: =(Parameters!$B$19*(E7+Parameters!$B$20)^S7+Parameters!$B$18*F7^S7)^(1/S7) -> 0.47527918 | V7: =(Parameters!$B$10*G7^Parameters!$B$9+Parameters!$B$11*U7^Parameters!$B$9)^(Parameters!$B$7/Parameters!$B$9)*N7 -> 1.4763946 | W7: =V7 - C7 - D7 - LN(1+EXP(Parameters!$B$21*B7))/Parameters!$B$21 - IF(B7>0, 0,Parameters!$B$6*B7^2/E7) -> 1.1883001 | X7: =EXP(-Parameters!$B$56*A7) -> 0.95571073 | Y7: =IF(W7>0,W7^(1-Parameters!$B$53)/(1-Parameters!$B$53)*X7*Parameters!$B$71,-10+W7*1000) -> -2.5705986 | AB7: =C7/F7-C6/F6 -> -0.0075710139 | AC7: =D7/G7-D6/G6 -> -0.00063643632 | AD7: =X7*(AA7^2+AB7^2+AC7^2) -> 5.5168691e-05 | AF7: =C7/F7-2*C6/F6+C5/F5 -> -0.0019144553 | AG7: =D7/G7-2*D6/G6+D5/G5 -> 0.00024557397 | AH7: =X7*(AE7^2+AF7^2+AG7^2) -> 3.5604483e-06 | AJ7: FD | AK7: 1 | AM7: =H7*I7*J7 -> 3.2606193 | AN7: =E7*I7*J7 -> 48.203919 | AO7: =U7*I7*J7 -> 37.582451 | AP7: =V7*J7*I7 -> 116.74513 | AQ7: =-X7*V7*W7^(-Parameters!B$53)*Parameters!B$47*Parameters!B$46*M7 -> -1.9557288e-05 | AR7: =1000*EXP(-(Parameters!$B$55)*'6states'!A7)*AP7*Parameters!B$47*Parameters!B$46*M7 -> 1.8383896 | AS7: =SUM(AR7:AR$204)*EXP(Parameters!$B$55*A7) -> 184.39915 | AT7: =((B7>0)*B7+C7+D7)/V7 -> 0.19477702 | AU7: =(1/$S7-1/Parameters!$B$13) * LN(Parameters!$B$18) / LN(O7) -> 0.2511409 | AV7: =(Parameters!$B$18*'6states'!S7^+Parameters!$B$19*Parameters!$B$25^'6states'!S7)^((1-'6states'!S7)/'6states'!S7)*Parameters!$B$18*Parameters!$B$26^('6states'!S7-1) -> 0.15814998 | AW7: =(LN(AV7)-LN(AV$4))/ LN(O7) -> 0.32633984 | AX7: =1-2^-AU7 -> 0.15976831 | AY7: =1-2^-AV7 -> 0.10382647 | AZ7: =(1/$S7-1/Parameters!$B$13) * LN(Parameters!$B$18) / A7 -> 0.050807373
A8: =A7+Parameters!$B$71 -> 4 | B8: -0.0039105241 | C8: 0.050910123 | D8: 0.2355976 | E8: =MAX((1-Parameters!$B$4)^Parameters!B$71*E7 + B7*Parameters!B$71 - IF(B7>0,Parameters!$B$5,0)*B7^2/E7*Parameters!B$71, 0.0001) -> 0.5663668 | F8: =(1-Parameters!$B$4)^Parameters!B$71*F7+C7*Parameters!B$71-Parameters!$B$5*C7^2/F7*Parameters!B$71 -> 0.23663539 | G8: =(1-Parameters!$B$4)^Parameters!B$71*G7+D7*Parameters!B$71-Parameters!$B$5*D7^2/G7*Parameters!B$71 -> 4.2024879 | H8: =MAX(H7 * (1-Parameters!$B$4) ^ Parameters!B$71 + (LN(1+EXP(Parameters!$B$21*(-B7+0.004)))/Parameters!$B$21 -0.004) * Parameters!B$71,0) -> 0.043602253 | I8: =I7*(1+Parameters!$B$52)^Parameters!B$71 -> 8.2550686 | J8: =J7*(1+Parameters!$B$54)^Parameters!B$71 -> 9.7988122 | K8: =I8*J8*EXP(-Parameters!$B$43*'6states'!A8)*(Parameters!$B$38/Parameters!$B$39*('6states'!E8+'6states'!H8)/Parameters!$E$25*(EXP(-Parameters!$B$39*Parameters!$E$25*'6states'!H8/('6states'!E8+'6states'!H8))-EXP(-Parameters!$B$39*Parameters!$E$25)) + Parameters!$B$40*'6states'!E8) -> 34.085065 | L8: =L7+K8*Parameters!B$71 -> 2451.9466 | M8: =L8*Parameters!$B$46 -> 1.471168 | N8: =EXP(-Parameters!$B$47/2*M8^2) -> 0.97848329 | O8: =MAX((Parameters!$B$63 + Parameters!$B$31*'6states'!A8 - '6states'!L8 + Parameters!$B$48/Parameters!$B$46)/Parameters!B$63,1) -> 2.217068 | P8: =Parameters!B$62*EXP(-Parameters!B$61*A8) -> 0.4488138 | Q8: =(1-Parameters!B$62)*O8^-Parameters!B$64 -> 0.46173426 | R8: =Parameters!B$62*EXP(-Parameters!B$61*A8)+(1-Parameters!B$62)*O8^-Parameters!B$64 -> 0.91054806 | S8: =1-R8/Parameters!$B$12 -> 0.54472597 | T8: =1/(1-S8) -> 2.1964793 | U8: =(Parameters!$B$19*(E8+Parameters!$B$20)^S8+Parameters!$B$18*F8^S8)^(1/S8) -> 0.45890198 | V8: =(Parameters!$B$10*G8^Parameters!$B$9+Parameters!$B$11*U8^Parameters!$B$9)^(Parameters!$B$7/Parameters!$B$9)*N8 -> 1.4681993 | W8: =V8 - C8 - D8 - LN(1+EXP(Parameters!$B$21*B8))/Parameters!$B$21 - IF(B8>0, 0,Parameters!$B$6*B8^2/E8) -> 1.1810816 | X8: =EXP(-Parameters!$B$56*A8) -> 0.9413879 | Y8: =IF(W8>0,W8^(1-Parameters!$B$53)/(1-Parameters!$B$53)*X8*Parameters!$B$71,-10+W8*1000) -> -2.5374799 | AB8: =C8/F8-C7/F7 -> -0.0089543301 | AC8: =D8/G8-D7/G7 -> -0.00046228191 | AD8: =X8*(AA8^2+AB8^2+AC8^2) -> 7.5681686e-05 | AF8: =C8/F8-2*C7/F7+C6/F6 -> -0.0013833161 | AG8: =D8/G8-2*D7/G7+D6/G6 -> 0.00017415442 | AH8: =X8*(AE8^2+AF8^2+AG8^2) -> 1.8299577e-06 | AJ8: SD | AK8: 0.3 | AM8: =H8*I8*J8 -> 3.5269804 | AN8: =E8*I8*J8 -> 45.813335 | AO8: =U8*I8*J8 -> 37.12052 | AP8: =V8*J8*I8 -> 118.76245 | AQ8: =-X8*V8*W8^(-Parameters!B$53)*Parameters!B$47*Parameters!B$46*M8 -> -1.9587785e-05 | AR8: =1000*EXP(-(Parameters!$B$55)*'6states'!A8)*AP8*Parameters!B$47*Parameters!B$46*M8 -> 1.8311072 | AS8: =SUM(AR8:AR$204)*EXP(Parameters!$B$55*A8) -> 188.87099 | AT8: =((B8>0)*B8+C8+D8)/V8 -> 0.19514225 | AU8: =(1/$S8-1/Parameters!$B$13) * LN(Parameters!$B$18) / LN(O8) -> 0.2457032 | AV8: =(Parameters!$B$18*'6states'!S8^+Parameters!$B$19*Parameters!$B$25^'6states'!S8)^((1-'6states'!S8)/'6states'!S8)*Parameters!$B$18*Parameters!$B$26^('6states'!S8-1) -> 0.16676645 | AW8: =(LN(AV8)-LN(AV$4))/ LN(O8) -> 0.31539412 | AX8: =1-2^-AU8 -> 0.1565954 | AY8: =1-2^-AV8 -> 0.1091629 | AZ8: =(1/$S8-1/Parameters!$B$13) * LN(Parameters!$B$18) / A8 -> 0.048906338
A9: =A8+Parameters!$B$71 -> 5 | B9: -0.0030479352 | C9: 0.05370798 | D9: 0.23249509 | E9: =MAX((1-Parameters!$B$4)^Parameters!B$71*E8 + B8*Parameters!B$71 - IF(B8>0,Parameters!$B$5,0)*B8^2/E8*Parameters!B$71, 0.0001) -> 0.52683181 | F9: =(1-Parameters!$B$4)^Parameters!B$71*F8+C8*Parameters!B$71-Parameters!$B$5*C8^2/F8*Parameters!B$71 -> 0.26170826 | G9: =(1-Parameters!$B$4)^Parameters!B$71*G8+D8*Parameters!B$71-Parameters!$B$5*D8^2/G8*Parameters!B$71 -> 4.160541 | H9: =MAX(H8 * (1-Parameters!$B$4) ^ Parameters!B$71 + (LN(1+EXP(Parameters!$B$21*(-B8+0.004)))/Parameters!$B$21 -0.004) * Parameters!B$71,0) -> 0.044873644 | I9: =I8*(1+Parameters!$B$52)^Parameters!B$71 -> 8.2790082 | J9: =J8*(1+Parameters!$B$54)^Parameters!B$71 -> 9.9947885 | K9: =I9*J9*EXP(-Parameters!$B$43*'6states'!A9)*(Parameters!$B$38/Parameters!$B$39*('6states'!E9+'6states'!H9)/Parameters!$E$25*(EXP(-Parameters!$B$39*Parameters!$E$25*'6states'!H9/('6states'!E9+'6states'!H9))-EXP(-Parameters!$B$39*Parameters!$E$25)) + Parameters!$B$40*'6states'!E9) -> 32.033807 | L9: =L8+K9*Parameters!B$71 -> 2483.9804 | M9: =L9*Parameters!$B$46 -> 1.4903882 | N9: =EXP(-Parameters!$B$47/2*M9^2) -> 0.97792369 | O9: =MAX((Parameters!$B$63 + Parameters!$B$31*'6states'!A9 - '6states'!L9 + Parameters!$B$48/Parameters!$B$46)/Parameters!B$63,1) -> 2.6403918 | P9: =Parameters!B$62*EXP(-Parameters!B$61*A9) -> 0.43685796 | Q9: =(1-Parameters!B$62)*O9^-Parameters!B$64 -> 0.45373592 | R9: =Parameters!B$62*EXP(-Parameters!B$61*A9)+(1-Parameters!B$62)*O9^-Parameters!B$64 -> 0.89059388 | S9: =1-R9/Parameters!$B$12 -> 0.55470306 | T9: =1/(1-S9) -> 2.2456925 | U9: =(Parameters!$B$19*(E9+Parameters!$B$20)^S9+Parameters!$B$18*F9^S9)^(1/S9) -> 0.44408215 | V9: =(Parameters!$B$10*G9^Parameters!$B$9+Parameters!$B$11*U9^Parameters!$B$9)^(Parameters!$B$7/Parameters!$B$9)*N9 -> 1.4600313 | W9: =V9 - C9 - D9 - LN(1+EXP(Parameters!$B$21*B9))/Parameters!$B$21 - IF(B9>0, 0,Parameters!$B$6*B9^2/E9) -> 1.1730929 | X9: =EXP(-Parameters!$B$56*A9) -> 0.92727973 | Y9: =IF(W9>0,W9^(1-Parameters!$B$53)/(1-Parameters!$B$53)*X9*Parameters!$B$71,-10+W9*1000) -> -2.505396 | AA9: =B9/E9-B8/E8 -> 0.0011191738 | AB9: =C9/F9-C8/F8 -> -0.0099208224 | AC9: =D9/G9-D8/G8 -> -0.00018048308 | AD9: =X9*(AA9^2+AB9^2+AC9^2) -> 9.2457059e-05 | AE9: =B9/E9-2*B8/E8+B7/E7 -> 8.5276029e-07 | AF9: =C9/F9-2*C8/F8+C7/F7 -> -0.0009664923 | AG9: =D9/G9-2*D8/G8+D7/G7 -> 0.00028179882 | AH9: =X9*(AE9^2+AF9^2+AG9^2) -> 9.3981532e-07 | AM9: =H9*I9*J9 -> 3.7131566 | AN9: =E9*I9*J9 -> 43.593718 | AO9: =U9*I9*J9 -> 36.746438 | AP9: =V9*J9*I9 -> 120.81312 | AQ9: =-X9*V9*W9^(-Parameters!B$53)*Parameters!B$47*Parameters!B$46*M9 -> -1.9616473e-05 | AR9: =1000*EXP(-(Parameters!$B$55)*'6states'!A9)*AP9*Parameters!B$47*Parameters!B$46*M9 -> 1.8219738 | AS9: =SUM(AR9:AR$204)*EXP(Parameters!$B$55*A9) -> 193.43569 | AT9: =((B9>0)*B9+C9+D9)/V9 -> 0.1960253 | AU9: =(1/$S9-1/Parameters!$B$13) * LN(Parameters!$B$18) / LN(O9) -> 0.24199578 | AV9: =(Parameters!$B$18*'6states'!S9^+Parameters!$B$19*Parameters!$B$25^'6states'!S9)^((1-'6states'!S9)/'6states'!S9)*Parameters!$B$18*Parameters!$B$26^('6states'!S9-1) -> 0.17479565 | AW9: =(LN(AV9)-LN(AV$4))/ LN(O9) -> 0.30706264 | AX9: =1-2^-AU9 -> 0.15442524 | AY9: =1-2^-AV9 -> 0.11410701 | AZ9: =(1/$S9-1/Parameters!$B$13) * LN(Parameters!$B$18) / A9 -> 0.046992063
A10: =A9+Parameters!$B$71 -> 6 | B10: -0.001397365 | C10: 0.056014686 | D10: 0.23090231 | E10: =MAX((1-Parameters!$B$4)^Parameters!B$71*E9 + B9*Parameters!B$71 - IF(B9>0,Parameters!$B$5,0)*B9^2/E9*Parameters!B$71, 0.0001) -> 0.49064615 | F10: =(1-Parameters!$B$4)^Parameters!B$71*F9+C9*Parameters!B$71-Parameters!$B$5*C9^2/F9*Parameters!B$71 -> 0.28793279 | G10: =(1-Parameters!$B$4)^Parameters!B$71*G9+D9*Parameters!B$71-Parameters!$B$5*D9^2/G9*Parameters!B$71 -> 4.118346 | H10: =MAX(H9 * (1-Parameters!$B$4) ^ Parameters!B$71 + (LN(1+EXP(Parameters!$B$21*(-B9+0.004)))/Parameters!$B$21 -0.004) * Parameters!B$71,0) -> 0.045243886 | I10: =I9*(1+Parameters!$B$52)^Parameters!B$71 -> 8.3030174 | J10: =J9*(1+Parameters!$B$54)^Parameters!B$71 -> 10.194684 | K10: =I10*J10*EXP(-Parameters!$B$43*'6states'!A10)*(Parameters!$B$38/Parameters!$B$39*('6states'!E10+'6states'!H10)/Parameters!$E$25*(EXP(-Parameters!$B$39*Parameters!$E$25*'6states'!H10/('6states'!E10+'6states'!H10))-EXP(-Parameters!$B$39*Parameters!$E$25)) + Parameters!$B$40*'6states'!E10) -> 30.167742 | L10: =L9+K10*Parameters!B$71 -> 2514.1482 | M10: =L10*Parameters!$B$46 -> 1.5084889 | N10: =EXP(-Parameters!$B$47/2*M10^2) -> 0.97739035 | O10: =MAX((Parameters!$B$63 + Parameters!$B$31*'6states'!A10 - '6states'!L10 + Parameters!$B$48/Parameters!$B$46)/Parameters!B$63,1) -> 3.101037 | P10: =Parameters!B$62*EXP(-Parameters!B$61*A10) -> 0.4252206 | Q10: =(1-Parameters!B$62)*O10^-Parameters!B$64 -> 0.44649779 | R10: =Parameters!B$62*EXP(-Parameters!B$61*A10)+(1-Parameters!B$62)*O10^-Parameters!B$64 -> 0.87171839 | S10: =1-R10/Parameters!$B$12 -> 0.56414081 | T10: =1/(1-S10) -> 2.2943189 | U10: =(Parameters!$B$19*(E10+Parameters!$B$20)^S10+Parameters!$B$18*F10^S10)^(1/S10) -> 0.43065414 | V10: =(Parameters!$B$10*G10^Parameters!$B$9+Parameters!$B$11*U10^Parameters!$B$9)^(Parameters!$B$7/Parameters!$B$9)*N10 -> 1.4520046 | W10: =V10 - C10 - D10 - LN(1+EXP(Parameters!$B$21*B10))/Parameters!$B$21 - IF(B10>0, 0,Parameters!$B$6*B10^2/E10) -> 1.1639371 | X10: =EXP(-Parameters!$B$56*A10) -> 0.91338299 | Y10: =IF(W10>0,W10^(1-Parameters!$B$53)/(1-Parameters!$B$53)*X10*Parameters!$B$71,-10+W10*1000) -> -2.4746258 | AA10: =B10/E10-B9/E9 -> 0.002937395 | AB10: =C10/F10-C9/F9 -> -0.010679972 | AC10: =D10/G10-D9/G9 -> 0.00018578212 | AD10: =X10*(AA10^2+AB10^2+AC10^2) -> 0.00011209457 | AE10: =B10/E10-2*B9/E9+B8/E8 -> 0.0018182211 | AF10: =C10/F10-2*C9/F9+C8/F8 -> -0.00075914961 | AG10: =D10/G10-2*D9/G9+D8/G8 -> 0.00036626521 | AH10: =X10*(AE10^2+AF10^2+AG10^2) -> 3.6684991e-06 | AM10: =H10*I10*J10 -> 3.8297429 | AN10: =E10*I10*J10 -> 41.531548 | AO10: =U10*I10*J10 -> 36.453426 | AP10: =V10*J10*I10 -> 122.90731 | AQ10: =-X10*V10*W10^(-Parameters!B$53)*Parameters!B$47*Parameters!B$46*M10 -> -1.9656468e-05 | AR10: =1000*EXP(-(Parameters!$B$55)*'6states'!A10)*AP10*Parameters!B$47*Parameters!B$46*M10 -> 1.8113598 | AS10: =SUM(AR10:AR$204)*EXP(Parameters!$B$55*A10) -> 198.09677 | AT10: =((B10>0)*B10+C10+D10)/V10 -> 0.19760061 | AU10: =(1/$S10-1/Parameters!$B$13) * LN(Parameters!$B$18) / LN(O10) -> 0.23935638 | AV10: =(Parameters!$B$18*'6states'!S10^+Parameters!$B$19*Parameters!$B$25^'6states'!S10)^((1-'6states'!S10)/'6states'!S10)*Parameters!$B$18*Parameters!$B$26^('6states'!S10-1) -> 0.18226504 | AW10: =(LN(AV10)-LN(AV$4))/ LN(O10) -> 0.30040545 | AX10: =1-2^-AU10 -> 0.15287685 | AY10: =1-2^-AV10 -> 0.11868177 | AZ10: =(1/$S10-1/Parameters!$B$13) * LN(Parameters!$B$18) / A10 -> 0.045148061
A11: =A10+Parameters!$B$71 -> 7 | B11: -0.0035797568 | C11: 0.057714133 | D11: 0.23026833 | E11: =MAX((1-Parameters!$B$4)^Parameters!B$71*E10 + B10*Parameters!B$71 - IF(B10>0,Parameters!$B$5,0)*B10^2/E10*Parameters!B$71, 0.0001) -> 0.45838714 | F11: =(1-Parameters!$B$4)^Parameters!B$71*F10+C10*Parameters!B$71-Parameters!$B$5*C10^2/F10*Parameters!B$71 -> 0.31493936 | G11: =(1-Parameters!$B$4)^Parameters!B$71*G10+D10*Parameters!B$71-Parameters!$B$5*D10^2/G10*Parameters!B$71 -> 4.0772584 | H11: =MAX(H10 * (1-Parameters!$B$4) ^ Parameters!B$71 + (LN(1+EXP(Parameters!$B$21*(-B10+0.004)))/Parameters!$B$21 -0.004) * Parameters!B$71,0) -> 0.044068548 | I11: =I10*(1+Parameters!$B$52)^Parameters!B$71 -> 8.3270961 | J11: =J10*(1+Parameters!$B$54)^Parameters!B$71 -> 10.398578 | K11: =I11*J11*EXP(-Parameters!$B$43*'6states'!A11)*(Parameters!$B$38/Parameters!$B$39*('6states'!E11+'6states'!H11)/Parameters!$E$25*(EXP(-Parameters!$B$39*Parameters!$E$25*'6states'!H11/('6states'!E11+'6states'!H11))-EXP(-Parameters!$B$39*Parameters!$E$25)) + Parameters!$B$40*'6states'!E11) -> 28.524176 | L11: =L10+K11*Parameters!B$71 -> 2542.6723 | M11: =L11*Parameters!$B$46 -> 1.5256034 | N11: =EXP(-Parameters!$B$47/2*M11^2) -> 0.97688042 | O11: =MAX((Parameters!$B$63 + Parameters!$B$31*'6states'!A11 - '6states'!L11 + Parameters!$B$48/Parameters!$B$46)/Parameters!B$63,1) -> 3.5945535 | P11: =Parameters!B$62*EXP(-Parameters!B$61*A11) -> 0.41389325 | Q11: =(1-Parameters!B$62)*O11^-Parameters!B$64 -> 0.43995222 | R11: =Parameters!B$62*EXP(-Parameters!B$61*A11)+(1-Parameters!B$62)*O11^-Parameters!B$64 -> 0.85384547 | S11: =1-R11/Parameters!$B$12 -> 0.57307727 | T11: =1/(1-S11) -> 2.3423442 | U11: =(Parameters!$B$19*(E11+Parameters!$B$20)^S11+Parameters!$B$18*F11^S11)^(1/S11) -> 0.41903474 | V11: =(Parameters!$B$10*G11^Parameters!$B$9+Parameters!$B$11*U11^Parameters!$B$9)^(Parameters!$B$7/Parameters!$B$9)*N11 -> 1.4444336 | W11: =V11 - C11 - D11 - LN(1+EXP(Parameters!$B$21*B11))/Parameters!$B$21 - IF(B11>0, 0,Parameters!$B$6*B11^2/E11) -> 1.1557759 | X11: =EXP(-Parameters!$B$56*A11) -> 0.89969452 | Y11: =IF(W11>0,W11^(1-Parameters!$B$53)/(1-Parameters!$B$53)*X11*Parameters!$B$71,-10+W11*1000) -> -2.4435502 | AA11: =B11/E11-B10/E10 -> -0.0049614519 | AB11: =C11/F11-C10/F10 -> -0.011286087 | AC11: =D11/G11-D10/G10 -> 0.000409507 | AD11: =X11*(AA11^2+AB11^2+AC11^2) -> 0.00013689704 | AE11: =B11/E11-2*B10/E10+B9/E9 -> -0.0078988469 | AF11: =C11/F11-2*C10/F10+C9/F9 -> -0.00060611539 | AG11: =D11/G11-2*D10/G10+D9/G9 -> 0.00022372487 | AH11: =X11*(AE11^2+AF11^2+AG11^2) -> 5.6509102e-05 | AM11: =H11*I11*J11 -> 3.8158937 | AN11: =E11*I11*J11 -> 39.691723 | AO11: =U11*I11*J11 -> 36.284201 | AP11: =V11*J11*I11 -> 125.07344 | AQ11: =-X11*V11*W11^(-Parameters!B$53)*Parameters!B$47*Parameters!B$46*M11 -> -1.9665374e-05 | AR11: =1000*EXP(-(Parameters!$B$55)*'6states'!A11)*AP11*Parameters!B$47*Parameters!B$46*M11 -> 1.799898 | AS11: =SUM(AR11:AR$204)*EXP(Parameters!$B$55*A11) -> 202.85758 | AT11: =((B11>0)*B11+C11+D11)/V11 -> 0.19937398 | AU11: =(1/$S11-1/Parameters!$B$13) * LN(Parameters!$B$18) / LN(O11) -> 0.23746494 | AV11: =(Parameters!$B$18*'6states'!S11^+Parameters!$B$19*Parameters!$B$25^'6states'!S11)^((1-'6states'!S11)/'6states'!S11)*Parameters!$B$18*Parameters!$B$26^('6states'!S11-1) -> 0.18920883 | AW11: =(LN(AV11)-LN(AV$4))/ LN(O11) -> 0.29495342 | AX11: =1-2^-AU11 -> 0.15176551 | AY11: =1-2^-AV11 -> 0.12291342 | AZ11: =(1/$S11-1/Parameters!$B$13) * LN(Parameters!$B$18) / A11 -> 0.043402478
A12: =A11+Parameters!$B$71 -> 8 | B12: -0.00065021139 | C12: 0.058701307 | D12: 0.22970673 | E12: =MAX((1-Parameters!$B$4)^Parameters!B$71*E11 + B11*Parameters!B$71 - IF(B11>0,Parameters!$B$5,0)*B11^2/E11*Parameters!B$71, 0.0001) -> 0.42597484 | F12: =(1-Parameters!$B$4)^Parameters!B$71*F11+C11*Parameters!B$71-Parameters!$B$5*C11^2/F11*Parameters!B$71 -> 0.34226742 | G12: =(1-Parameters!$B$4)^Parameters!B$71*G11+D11*Parameters!B$71-Parameters!$B$5*D11^2/G11*Parameters!B$71 -> 4.0380625 | H12: =MAX(H11 * (1-Parameters!$B$4) ^ Parameters!B$71 + (LN(1+EXP(Parameters!$B$21*(-B11+0.004)))/Parameters!$B$21 -0.004) * Parameters!B$71,0) -> 0.044994136 | I12: =I11*(1+Parameters!$B$52)^Parameters!B$71 -> 8.3512447 | J12: =J11*(1+Parameters!$B$54)^Parameters!B$71 -> 10.606549 | K12: =I12*J12*EXP(-Parameters!$B$43*'6states'!A12)*(Parameters!$B$38/Parameters!$B$39*('6states'!E12+'6states'!H12)/Parameters!$E$25*(EXP(-Parameters!$B$39*Parameters!$E$25*'6states'!H12/('6states'!E12+'6states'!H12))-EXP(-Parameters!$B$39*Parameters!$E$25)) + Parameters!$B$40*'6states'!E12) -> 26.80968 | L12: =L11+K12*Parameters!B$71 -> 2569.482 | M12: =L12*Parameters!$B$46 -> 1.5416892 | N12: =EXP(-Parameters!$B$47/2*M12^2) -> 0.97639614 | O12: =MAX((Parameters!$B$63 + Parameters!$B$31*'6states'!A12 - '6states'!L12 + Parameters!$B$48/Parameters!$B$46)/Parameters!B$63,1) -> 4.1223599 | P12: =Parameters!B$62*EXP(-Parameters!B$61*A12) -> 0.40286765 | Q12: =(1-Parameters!B$62)*O12^-Parameters!B$64 -> 0.43396571 | R12: =Parameters!B$62*EXP(-Parameters!B$61*A12)+(1-Parameters!B$62)*O12^-Parameters!B$64 -> 0.83683336 | S12: =1-R12/Parameters!$B$12 -> 0.58158332 | T12: =1/(1-S12) -> 2.3899621 | U12: =(Parameters!$B$19*(E12+Parameters!$B$20)^S12+Parameters!$B$18*F12^S12)^(1/S12) -> 0.40650392 | V12: =(Parameters!$B$10*G12^Parameters!$B$9+Parameters!$B$11*U12^Parameters!$B$9)^(Parameters!$B$7/Parameters!$B$9)*N12 -> 1.436471 | W12: =V12 - C12 - D12 - LN(1+EXP(Parameters!$B$21*B12))/Parameters!$B$21 - IF(B12>0, 0,Parameters!$B$6*B12^2/E12) -> 1.1466291 | X12: =EXP(-Parameters!$B$56*A12) -> 0.88621118 | Y12: =IF(W12>0,W12^(1-Parameters!$B$53)/(1-Parameters!$B$53)*X12*Parameters!$B$71,-10+W12*1000) -> -2.4136325 | AA12: =B12/E12-B11/E11 -> 0.0062830536 | AB12: =C12/F12-C11/F11 -> -0.011747605 | AC12: =D12/G12-D11/G11 -> 0.00040911705 | AD12: =X12*(AA12^2+AB12^2+AC12^2) -> 0.00015743573 | AE12: =B12/E12-2*B11/E11+B10/E10 -> 0.011244505 | AF12: =C12/F12-2*C11/F11+C10/F10 -> -0.00046151742 | AG12: =D12/G12-2*D11/G11+D10/G10 -> -3.8994925e-07 | AH12: =X12*(AE12^2+AF12^2+AG12^2) -> 0.00011224033 | AM12: =H12*I12*J12 -> 3.9854856 | AN12: =E12*I12*J12 -> 37.731952 | AO12: =U12*I12*J12 -> 36.007259 | AP12: =V12*J12*I12 -> 127.23957 | AQ12: =-X12*V12*W12^(-Parameters!B$53)*Parameters!B$47*Parameters!B$46*M12 -> -1.9676924e-05 | AR12: =1000*EXP(-(Parameters!$B$55)*'6states'!A12)*AP12*Parameters!B$47*Parameters!B$46*M12 -> 1.7865552 | AS12: =SUM(AR12:AR$204)*EXP(Parameters!$B$55*A12) -> 207.72092 | AT12: =((B12>0)*B12+C12+D12)/V12 -> 0.2007754 | AU12: =(1/$S12-1/Parameters!$B$13) * LN(Parameters!$B$18) / LN(O12) -> 0.23596037 | AV12: =(Parameters!$B$18*'6states'!S12^+Parameters!$B$19*Parameters!$B$25^'6states'!S12)^((1-'6states'!S12)/'6states'!S12)*Parameters!$B$18*Parameters!$B$26^('6states'!S12-1) -> 0.19568911 | AW12: =(LN(AV12)-LN(AV$4))/ LN(O12) -> 0.29019885 | AX12: =1-2^-AU12 -> 0.15088043 | AY12: =1-2^-AV12 -> 0.12684427 | AZ12: =(1/$S12-1/Parameters!$B$13) * LN(Parameters!$B$18) / A12 -> 0.041777544
A13: =A12+Parameters!$B$71 -> 9 | B13: 0.014940549 | C13: 0.05910464 | D13: 0.22364574 | E13: =MAX((1-Parameters!$B$4)^Parameters!B$71*E12 + B12*Parameters!B$71 - IF(B12>0,Parameters!$B$5,0)*B12^2/E12*Parameters!B$71, 0.0001) -> 0.39853081 | F13: =(1-Parameters!$B$4)^Parameters!B$71*F12+C12*Parameters!B$71-Parameters!$B$5*C12^2/F12*Parameters!B$71 -> 0.36937241 | G13: =(1-Parameters!$B$4)^Parameters!B$71*G12+D12*Parameters!B$71-Parameters!$B$5*D12^2/G12*Parameters!B$71 -> 4.0007082 | H13: =MAX(H12 * (1-Parameters!$B$4) ^ Parameters!B$71 + (LN(1+EXP(Parameters!$B$21*(-B12+0.004)))/Parameters!$B$21 -0.004) * Parameters!B$71,0) -> 0.043175894 | I13: =I12*(1+Parameters!$B$52)^Parameters!B$71 -> 8.3754633 | J13: =J12*(1+Parameters!$B$54)^Parameters!B$71 -> 10.81868 | K13: =I13*J13*EXP(-Parameters!$B$43*'6states'!A13)*(Parameters!$B$38/Parameters!$B$39*('6states'!E13+'6states'!H13)/Parameters!$E$25*(EXP(-Parameters!$B$39*Parameters!$E$25*'6states'!H13/('6states'!E13+'6states'!H13))-EXP(-Parameters!$B$39*Parameters!$E$25)) + Parameters!$B$40*'6states'!E13) -> 25.395104 | L13: =L12+K13*Parameters!B$71 -> 2594.8771 | M13: =L13*Parameters!$B$46 -> 1.5569263 | N13: =EXP(-Parameters!$B$47/2*M13^2) -> 0.97593295 | O13: =MAX((Parameters!$B$63 + Parameters!$B$31*'6states'!A13 - '6states'!L13 + Parameters!$B$48/Parameters!$B$46)/Parameters!B$63,1) -> 4.6784578 | P13: =Parameters!B$62*EXP(-Parameters!B$61*A13) -> 0.39213576 | Q13: =(1-Parameters!B$62)*O13^-Parameters!B$64 -> 0.42850879 | R13: =Parameters!B$62*EXP(-Parameters!B$61*A13)+(1-Parameters!B$62)*O13^-Parameters!B$64 -> 0.82064454 | S13: =1-R13/Parameters!$B$12 -> 0.58967773 | T13: =1/(1-S13) -> 2.4371088 | U13: =(Parameters!$B$19*(E13+Parameters!$B$20)^S13+Parameters!$B$18*F13^S13)^(1/S13) -> 0.39646223 | V13: =(Parameters!$B$10*G13^Parameters!$B$9+Parameters!$B$11*U13^Parameters!$B$9)^(Parameters!$B$7/Parameters!$B$9)*N13 -> 1.4293618 | W13: =V13 - C13 - D13 - LN(1+EXP(Parameters!$B$21*B13))/Parameters!$B$21 - IF(B13>0, 0,Parameters!$B$6*B13^2/E13) -> 1.1316645 | X13: =EXP(-Parameters!$B$56*A13) -> 0.87292992 | Y13: =IF(W13>0,W13^(1-Parameters!$B$53)/(1-Parameters!$B$53)*X13*Parameters!$B$71,-10+W13*1000) -> -2.3884169 | AA13: =B13/E13-B12/E12 -> 0.039015476 | AB13: =C13/F13-C12/F12 -> -0.01149346 | AC13: =D13/G13-D12/G12 -> -0.00098384512 | AD13: =X13*(AA13^2+AB13^2+AC13^2) -> 0.0014449391 | AE13: =B13/E13-2*B12/E12+B11/E11 -> 0.032732423 | AF13: =C13/F13-2*C12/F12+C11/F11 -> 0.00025414496 | AG13: =D13/G13-2*D12/G12+D11/G11 -> -0.0013929622 | AH13: =X13*(AE13^2+AF13^2+AG13^2) -> 0.00093701733 | AM13: =H13*I13*J13 -> 3.9122309 | AN13: =E13*I13*J13 -> 36.111459 | AO13: =U13*I13*J13 -> 35.924022 | AP13: =V13*J13*I13 -> 129.51656 | AQ13: =-X13*V13*W13^(-Parameters!B$53)*Parameters!B$47*Parameters!B$46*M13 -> -1.982522e-05 | AR13: =1000*EXP(-(Parameters!$B$55)*'6states'!A13)*AP13*Parameters!B$47*Parameters!B$46*M13 -> 1.7731563 | AS13: =SUM(AR13:AR$204)*EXP(Parameters!$B$55*A13) -> 212.69114 | AT13: =((B13>0)*B13+C13+D13)/V13 -> 0.20826843 | AU13: =(1/$S13-1/Parameters!$B$13) * LN(Parameters!$B$18) / LN(O13) -> 0.23483145 | AV13: =(Parameters!$B$18*'6states'!S13^+Parameters!$B$19*Parameters!$B$25^'6states'!S13)^((1-'6states'!S13)/'6states'!S13)*Parameters!$B$18*Parameters!$B$26^('6states'!S13-1) -> 0.20172899 | AW13: =(LN(AV13)-LN(AV$4))/ LN(O13) -> 0.28609987 | AX13: =1-2^-AU13 -> 0.15021573 | AY13: =1-2^-AV13 -> 0.13049212 | AZ13: =(1/$S13-1/Parameters!$B$13) * LN(Parameters!$B$18) / A13 -> 0.040259726
A14: =A13+Parameters!$B$71 -> 10 | B14: 0.024351969 | C14: 0.059466325 | D14: 0.22088997 | E14: =MAX((1-Parameters!$B$4)^Parameters!B$71*E13 + B13*Parameters!B$71 - IF(B13>0,Parameters!$B$5,0)*B13^2/E13*Parameters!B$71, 0.0001) -> 0.38784366 | F14: =(1-Parameters!$B$4)^Parameters!B$71*F13+C13*Parameters!B$71-Parameters!$B$5*C13^2/F13*Parameters!B$71 -> 0.39578598 | G14: =(1-Parameters!$B$4)^Parameters!B$71*G13+D13*Parameters!B$71-Parameters!$B$5*D13^2/G13*Parameters!B$71 -> 3.9602072 | H14: =MAX(H13 * (1-Parameters!$B$4) ^ Parameters!B$71 + (LN(1+EXP(Parameters!$B$21*(-B13+0.004)))/Parameters!$B$21 -0.004) * Parameters!B$71,0) -> 0.036491366 | I14: =I13*(1+Parameters!$B$52)^Parameters!B$71 -> 8.3997522 | J14: =J13*(1+Parameters!$B$54)^Parameters!B$71 -> 11.035054 | K14: =I14*J14*EXP(-Parameters!$B$43*'6states'!A14)*(Parameters!$B$38/Parameters!$B$39*('6states'!E14+'6states'!H14)/Parameters!$E$25*(EXP(-Parameters!$B$39*Parameters!$E$25*'6states'!H14/('6states'!E14+'6states'!H14))-EXP(-Parameters!$B$39*Parameters!$E$25)) + Parameters!$B$40*'6states'!E14) -> 25.080584 | L14: =L13+K14*Parameters!B$71 -> 2619.9577 | M14: =L14*Parameters!$B$46 -> 1.5719746 | N14: =EXP(-Parameters!$B$47/2*M14^2) -> 0.97547124 | O14: =MAX((Parameters!$B$63 + Parameters!$B$31*'6states'!A14 - '6states'!L14 + Parameters!$B$48/Parameters!$B$46)/Parameters!B$63,1) -> 5.2408461 | P14: =Parameters!B$62*EXP(-Parameters!B$61*A14) -> 0.38168975 | Q14: =(1-Parameters!B$62)*O14^-Parameters!B$64 -> 0.4236721 | R14: =Parameters!B$62*EXP(-Parameters!B$61*A14)+(1-Parameters!B$62)*O14^-Parameters!B$64 -> 0.80536185 | S14: =1-R14/Parameters!$B$12 -> 0.59731908 | T14: =1/(1-S14) -> 2.4833558 | U14: =(Parameters!$B$19*(E14+Parameters!$B$20)^S14+Parameters!$B$18*F14^S14)^(1/S14) -> 0.39721802 | V14: =(Parameters!$B$10*G14^Parameters!$B$9+Parameters!$B$11*U14^Parameters!$B$9)^(Parameters!$B$7/Parameters!$B$9)*N14 -> 1.4262004 | W14: =V14 - C14 - D14 - LN(1+EXP(Parameters!$B$21*B14))/Parameters!$B$21 - IF(B14>0, 0,Parameters!$B$6*B14^2/E14) -> 1.121492 | X14: =EXP(-Parameters!$B$56*A14) -> 0.8598477 | Y14: =IF(W14>0,W14^(1-Parameters!$B$53)/(1-Parameters!$B$53)*X14*Parameters!$B$71,-10+W14*1000) -> -2.3600697 | AA14: =B14/E14-B13/E13 -> 0.025299038 | AB14: =C14/F14-C13/F13 -> -0.0097649924 | AC14: =D14/G14-D13/G13 -> -0.00012415986 | AD14: =X14*(AA14^2+AB14^2+AC14^2) -> 0.00063234215 | AE14: =B14/E14-2*B13/E13+B12/E12 -> -0.013716439 | AF14: =C14/F14-2*C13/F13+C12/F12 -> 0.0017284674 | AG14: =D14/G14-2*D13/G13+D12/G12 -> 0.00085968526 | AH14: =X14*(AE14^2+AF14^2+AG14^2) -> 0.0001649767 | AM14: =H14*I14*J14 -> 3.3824475 | AN14: =E14*I14*J14 -> 35.949896 | AO14: =U14*I14*J14 -> 36.818821 | AP14: =V14*J14*I14 -> 132.19697 | AQ14: =-X14*V14*W14^(-Parameters!B$53)*Parameters!B$47*Parameters!B$46*M14 -> -1.9914531e-05 | AR14: =1000*EXP(-(Parameters!$B$55)*'6states'!A14)*AP14*Parameters!B$47*Parameters!B$46*M14 -> 1.7643184 | AS14: =SUM(AR14:AR$204)*EXP(Parameters!$B$55*A14) -> 217.77042 | AT14: =(B14+C14+D14)/V14 -> 0.21365039 | AU14: =(1/$S14-1/Parameters!$B$13) * LN(Parameters!$B$18) / LN(O14) -> 0.23434089 | AV14: =(Parameters!$B$18*'6states'!S14^+Parameters!$B$19*Parameters!$B$25^'6states'!S14)^((1-'6states'!S14)/'6states'!S14)*Parameters!$B$18*Parameters!$B$26^('6states'!S14-1) -> 0.20730973 | AW14: =(LN(AV14)-LN(AV$4))/ LN(O14) -> 0.28296812 | AX14: =1-2^-AU14 -> 0.14992673 | AY14: =1-2^-AV14 -> 0.13384911 | AZ14: =(1/$S14-1/Parameters!$B$13) * LN(Parameters!$B$18) / A14 -> 0.03881817
A15: =A14+Parameters!$B$71 -> 11 | B15: 0.0277171 | C15: 0.060311935 | D15: 0.22097238 | E15: =MAX((1-Parameters!$B$4)^Parameters!B$71*E14 + B14*Parameters!B$71 - IF(B14>0,Parameters!$B$5,0)*B14^2/E14*Parameters!B$71, 0.0001) -> 0.38627125 | F15: =(1-Parameters!$B$4)^Parameters!B$71*F14+C14*Parameters!B$71-Parameters!$B$5*C14^2/F14*Parameters!B$71 -> 0.42142263 | G15: =(1-Parameters!$B$4)^Parameters!B$71*G14+D14*Parameters!B$71-Parameters!$B$5*D14^2/G14*Parameters!B$71 -> 3.9196795 | H15: =MAX(H14 * (1-Parameters!$B$4) ^ Parameters!B$71 + (LN(1+EXP(Parameters!$B$21*(-B14+0.004)))/Parameters!$B$21 -0.004) * Parameters!B$71,0) -> 0.030196788 | I15: =I14*(1+Parameters!$B$52)^Parameters!B$71 -> 8.4241114 | J15: =J14*(1+Parameters!$B$54)^Parameters!B$71 -> 11.255755 | K15: =I15*J15*EXP(-Parameters!$B$43*'6states'!A15)*(Parameters!$B$38/Parameters!$B$39*('6states'!E15+'6states'!H15)/Parameters!$E$25*(EXP(-Parameters!$B$39*Parameters!$E$25*'6states'!H15/('6states'!E15+'6states'!H15))-EXP(-Parameters!$B$39*Parameters!$E$25)) + Parameters!$B$40*'6states'!E15) -> 25.397481 | L15: =L14+K15*Parameters!B$71 -> 2645.3552 | M15: =L15*Parameters!$B$46 -> 1.5872131 | N15: =EXP(-Parameters!$B$47/2*M15^2) -> 0.97499941 | O15: =MAX((Parameters!$B$63 + Parameters!$B$31*'6states'!A15 - '6states'!L15 + Parameters!$B$48/Parameters!$B$46)/Parameters!B$63,1) -> 5.7968965 | P15: =Parameters!B$62*EXP(-Parameters!B$61*A15) -> 0.37152201 | Q15: =(1-Parameters!B$62)*O15^-Parameters!B$64 -> 0.41942127 | R15: =Parameters!B$62*EXP(-Parameters!B$61*A15)+(1-Parameters!B$62)*O15^-Parameters!B$64 -> 0.79094327 | S15: =1-R15/Parameters!$B$12 -> 0.60452836 | T15: =1/(1-S15) -> 2.5286263 | U15: =(Parameters!$B$19*(E15+Parameters!$B$20)^S15+Parameters!$B$18*F15^S15)^(1/S15) -> 0.40384827 | V15: =(Parameters!$B$10*G15^Parameters!$B$9+Parameters!$B$11*U15^Parameters!$B$9)^(Parameters!$B$7/Parameters!$B$9)*N15 -> 1.425062 | W15: =V15 - C15 - D15 - LN(1+EXP(Parameters!$B$21*B15))/Parameters!$B$21 - IF(B15>0, 0,Parameters!$B$6*B15^2/E15) -> 1.1160606 | X15: =EXP(-Parameters!$B$56*A15) -> 0.84696153 | Y15: =IF(W15>0,W15^(1-Parameters!$B$53)/(1-Parameters!$B$53)*X15*Parameters!$B$71,-10+W15*1000) -> -2.3286538 | AA15: =B15/E15-B14/E14 -> 0.0089674291 | AB15: =C15/F15-C14/F14 -> -0.0071336042 | AC15: =D15/G15-D14/G14 -> 0.00059773625 | AD15: =X15*(AA15^2+AB15^2+AC15^2) -> 0.00011151128 | AE15: =B15/E15-2*B14/E14+B13/E13 -> -0.016331609 | AF15: =C15/F15-2*C14/F14+C13/F13 -> 0.0026313882 | AG15: =D15/G15-2*D14/G14+D13/G13 -> 0.00072189611 | AH15: =X15*(AE15^2+AF15^2+AG15^2) -> 0.00023220872 | AM15: =H15*I15*J15 -> 2.8632514 | AN15: =E15*I15*J15 -> 36.626138 | AO15: =U15*I15*J15 -> 38.292786 | AP15: =V15*J15*I15 -> 135.124 | AQ15: =-X15*V15*W15^(-Parameters!B$53)*Parameters!B$47*Parameters!B$46*M15 -> -1.9920559e-05 | AR15: =1000*EXP(-(Parameters!$B$55)*'6states'!A15)*AP15*Parameters!B$47*Parameters!B$46*M15 -> 1.7580611 | AS15: =SUM(AR15:AR$204)*EXP(Parameters!$B$55*A15) -> 222.95417 | AT15: =(B15+C15+D15)/V15 -> 0.21683366 | AU15: =(1/$S15-1/Parameters!$B$13) * LN(Parameters!$B$18) / LN(O15) -> 0.23442796 | AV15: =(Parameters!$B$18*'6states'!S15^+Parameters!$B$19*Parameters!$B$25^'6states'!S15)^((1-'6states'!S15)/'6states'!S15)*Parameters!$B$18*Parameters!$B$26^('6states'!S15-1) -> 0.21246127 | AW15: =(LN(AV15)-LN(AV$4))/ LN(O15) -> 0.28069838 | AX15: =1-2^-AU15 -> 0.14997803 | AY15: =1-2^-AV15 -> 0.13693643 | AZ15: =(1/$S15-1/Parameters!$B$13) * LN(Parameters!$B$18) / A15 -> 0.037451416
A16: =A15+Parameters!$B$71 -> 12 | B16: 0.025652145 | C16: 0.061999034 | D16: 0.22351418 | E16: =MAX((1-Parameters!$B$4)^Parameters!B$71*E15 + B15*Parameters!B$71 - IF(B15>0,Parameters!$B$5,0)*B15^2/E15*Parameters!B$71, 0.0001) -> 0.38770303 | F16: =(1-Parameters!$B$4)^Parameters!B$71*F15+C15*Parameters!B$71-Parameters!$B$5*C15^2/F15*Parameters!B$71 -> 0.44659553 | G16: =(1-Parameters!$B$4)^Parameters!B$71*G15+D15*Parameters!B$71-Parameters!$B$5*D15^2/G15*Parameters!B$71 -> 3.8816467 | H16: =MAX(H15 * (1-Parameters!$B$4) ^ Parameters!B$71 + (LN(1+EXP(Parameters!$B$21*(-B15+0.004)))/Parameters!$B$21 -0.004) * Parameters!B$71,0) -> 0.024297599 | I16: =I15*(1+Parameters!$B$52)^Parameters!B$71 -> 8.4485414 | J16: =J15*(1+Parameters!$B$54)^Parameters!B$71 -> 11.48087 | K16: =I16*J16*EXP(-Parameters!$B$43*'6states'!A16)*(Parameters!$B$38/Parameters!$B$39*('6states'!E16+'6states'!H16)/Parameters!$E$25*(EXP(-Parameters!$B$39*Parameters!$E$25*'6states'!H16/('6states'!E16+'6states'!H16))-EXP(-Parameters!$B$39*Parameters!$E$25)) + Parameters!$B$40*'6states'!E16) -> 25.995005 | L16: =L15+K16*Parameters!B$71 -> 2671.3502 | M16: =L16*Parameters!$B$46 -> 1.6028101 | N16: =EXP(-Parameters!$B$47/2*M16^2) -> 0.97451199 | O16: =MAX((Parameters!$B$63 + Parameters!$B$31*'6states'!A16 - '6states'!L16 + Parameters!$B$48/Parameters!$B$46)/Parameters!B$63,1) -> 6.3409964 | P16: =Parameters!B$62*EXP(-Parameters!B$61*A16) -> 0.36162512 | Q16: =(1-Parameters!B$62)*O16^-Parameters!B$64 -> 0.41567533 | R16: =Parameters!B$62*EXP(-Parameters!B$61*A16)+(1-Parameters!B$62)*O16^-Parameters!B$64 -> 0.77730045 | S16: =1-R16/Parameters!$B$12 -> 0.61134977 | T16: =1/(1-S16) -> 2.5730076 | U16: =(Parameters!$B$19*(E16+Parameters!$B$20)^S16+Parameters!$B$18*F16^S16)^(1/S16) -> 0.41232483 | V16: =(Parameters!$B$10*G16^Parameters!$B$9+Parameters!$B$11*U16^Parameters!$B$9)^(Parameters!$B$7/Parameters!$B$9)*N16 -> 1.4243407 | W16: =V16 - C16 - D16 - LN(1+EXP(Parameters!$B$21*B16))/Parameters!$B$21 - IF(B16>0, 0,Parameters!$B$6*B16^2/E16) -> 1.1131753 | X16: =EXP(-Parameters!$B$56*A16) -> 0.83426849 | Y16: =IF(W16>0,W16^(1-Parameters!$B$53)/(1-Parameters!$B$53)*X16*Parameters!$B$71,-10+W16*1000) -> -2.2958343 | AA16: =B16/E16-B15/E15 -> -0.0055911186 | AB16: =C16/F16-C15/F15 -> -0.0042891691 | AC16: =D16/G16-D15/G15 -> 0.0012071944 | AD16: =X16*(AA16^2+AB16^2+AC16^2) -> 4.2643548e-05 | AE16: =B16/E16-2*B15/E15+B14/E14 -> -0.014558548 | AF16: =C16/F16-2*C15/F15+C14/F14 -> 0.0028444351 | AG16: =D16/G16-2*D15/G15+D14/G14 -> 0.00060945813 | AH16: =X16*(AE16^2+AF16^2+AG16^2) -> 0.00018388409 | AM16: =H16*I16*J16 -> 2.3567847 | AN16: =E16*I16*J16 -> 37.605879 | AO16: =U16*I16*J16 -> 39.994109 | AP16: =V16*J16*I16 -> 138.15622 | AQ16: =-X16*V16*W16^(-Parameters!B$53)*Parameters!B$47*Parameters!B$46*M16 -> -1.9874138e-05 | AR16: =1000*EXP(-(Parameters!$B$55)*'6states'!A16)*AP16*Parameters!B$47*Parameters!B$46*M16 -> 1.7525684 | AS16: =SUM(AR16:AR$204)*EXP(Parameters!$B$55*A16) -> 228.23991 | AT16: =(B16+C16+D16)/V16 -> 0.21846272 | AU16: =(1/$S16-1/Parameters!$B$13) * LN(Parameters!$B$18) / LN(O16) -> 0.23494581 | AV16: =(Parameters!$B$18*'6states'!S16^+Parameters!$B$19*Parameters!$B$25^'6states'!S16)^((1-'6states'!S16)/'6states'!S16)*Parameters!$B$18*Parameters!$B$26^('6states'!S16-1) -> 0.2172296 | AW16: =(LN(AV16)-LN(AV$4))/ LN(O16) -> 0.27908108 | AX16: =1-2^-AU16 -> 0.15028308 | AY16: =1-2^-AV16 -> 0.13978428 | AZ16: =(1/$S16-1/Parameters!$B$13) * LN(Parameters!$B$18) / A16 -> 0.036162778
A17: =A16+Parameters!$B$71 -> 13 | B17: 0.016234739 | C17: 0.064698149 | D17: 0.22825968 | E17: =MAX((1-Parameters!$B$4)^Parameters!B$71*E16 + B16*Parameters!B$71 - IF(B16>0,Parameters!$B$5,0)*B16^2/E16*Parameters!B$71, 0.0001) -> 0.3872714 | F17: =(1-Parameters!$B$4)^Parameters!B$71*F16+C16*Parameters!B$71-Parameters!$B$5*C16^2/F16*Parameters!B$71 -> 0.47189663 | G17: =(1-Parameters!$B$4)^Parameters!B$71*G16+D16*Parameters!B$71-Parameters!$B$5*D16^2/G16*Parameters!B$71 -> 3.8481348 | H17: =MAX(H16 * (1-Parameters!$B$4) ^ Parameters!B$71 + (LN(1+EXP(Parameters!$B$21*(-B16+0.004)))/Parameters!$B$21 -0.004) * Parameters!B$71,0) -> 0.018769714 | I17: =I16*(1+Parameters!$B$52)^Parameters!B$71 -> 8.4730421 | J17: =J16*(1+Parameters!$B$54)^Parameters!B$71 -> 11.710488 | K17: =I17*J17*EXP(-Parameters!$B$43*'6states'!A17)*(Parameters!$B$38/Parameters!$B$39*('6states'!E17+'6states'!H17)/Parameters!$E$25*(EXP(-Parameters!$B$39*Parameters!$E$25*'6states'!H17/('6states'!E17+'6states'!H17))-EXP(-Parameters!$B$39*Parameters!$E$25)) + Parameters!$B$40*'6states'!E17) -> 26.589699 | L17: =L16+K17*Parameters!B$71 -> 2697.9399 | M17: =L17*Parameters!$B$46 -> 1.6187639 | N17: =EXP(-Parameters!$B$47/2*M17^2) -> 0.97400876 | O17: =MAX((Parameters!$B$63 + Parameters!$B$31*'6states'!A17 - '6states'!L17 + Parameters!$B$48/Parameters!$B$46)/Parameters!B$63,1) -> 6.8732024 | P17: =Parameters!B$62*EXP(-Parameters!B$61*A17) -> 0.35199188 | Q17: =(1-Parameters!B$62)*O17^-Parameters!B$64 -> 0.41233869 | R17: =Parameters!B$62*EXP(-Parameters!B$61*A17)+(1-Parameters!B$62)*O17^-Parameters!B$64 -> 0.76433057 | S17: =1-R17/Parameters!$B$12 -> 0.61783471 | T17: =1/(1-S17) -> 2.6166689 | U17: =(Parameters!$B$19*(E17+Parameters!$B$20)^S17+Parameters!$B$18*F17^S17)^(1/S17) -> 0.41942474 | V17: =(Parameters!$B$10*G17^Parameters!$B$9+Parameters!$B$11*U17^Parameters!$B$9)^(Parameters!$B$7/Parameters!$B$9)*N17 -> 1.4231437 | W17: =V17 - C17 - D17 - LN(1+EXP(Parameters!$B$21*B17))/Parameters!$B$21 - IF(B17>0, 0,Parameters!$B$6*B17^2/E17) -> 1.1139474 | X17: =EXP(-Parameters!$B$56*A17) -> 0.82176567 | Y17: =IF(W17>0,W17^(1-Parameters!$B$53)/(1-Parameters!$B$53)*X17*Parameters!$B$71,-10+W17*1000) -> -2.260879 | AA17: =B17/E17-B16/E16 -> -0.024243585 | AB17: =C17/F17-C16/F16 -> -0.0017235429 | AC17: =D17/G17-D16/G16 -> 0.0017346572 | AD17: =X17*(AA17^2+AB17^2+AC17^2) -> 0.00048790779 | AE17: =B17/E17-2*B16/E16+B15/E15 -> -0.018652466 | AF17: =C17/F17-2*C16/F16+C15/F15 -> 0.0025656261 | AG17: =D17/G17-2*D16/G16+D15/G15 -> 0.00052746279 | AH17: =X17*(AE17^2+AF17^2+AG17^2) -> 0.00029154205 | AM17: =H17*I17*J17 -> 1.8623958 | AN17: =E17*I17*J17 -> 38.426406 | AO17: =U17*I17*J17 -> 41.616772 | AP17: =V17*J17*I17 -> 141.20924 | AQ17: =-X17*V17*W17^(-Parameters!B$53)*Parameters!B$47*Parameters!B$46*M17 -> -1.9736052e-05 | AR17: =1000*EXP(-(Parameters!$B$55)*'6states'!A17)*AP17*Parameters!B$47*Parameters!B$46*M17 -> 1.7467283 | AS17: =SUM(AR17:AR$204)*EXP(Parameters!$B$55*A17) -> 233.62744 | AT17: =(B17+C17+D17)/V17 -> 0.21726026 | AU17: =(1/$S17-1/Parameters!$B$13) * LN(Parameters!$B$18) / LN(O17) -> 0.23573317 | AV17: =(Parameters!$B$18*'6states'!S17^+Parameters!$B$19*Parameters!$B$25^'6states'!S17)^((1-'6states'!S17)/'6states'!S17)*Parameters!$B$18*Parameters!$B$26^('6states'!S17-1) -> 0.22166368 | AW17: =(LN(AV17)-LN(AV$4))/ LN(O17) -> 0.27789521 | AX17: =1-2^-AU17 -> 0.1507467 | AY17: =1-2^-AV17 -> 0.14242407 | AZ17: =(1/$S17-1/Parameters!$B$13) * LN(Parameters!$B$18) / A17 -> 0.034954336
A18: =A17+Parameters!$B$71 -> 14 | B18: -0.00038015281 | C18: 0.068013288 | D18: 0.2331651 | E18: =MAX((1-Parameters!$B$4)^Parameters!B$71*E17 + B17*Parameters!B$71 - IF(B17>0,Parameters!$B$5,0)*B17^2/E17*Parameters!B$71, 0.0001) -> 0.37846619 | F18: =(1-Parameters!$B$4)^Parameters!B$71*F17+C17*Parameters!B$71-Parameters!$B$5*C17^2/F17*Parameters!B$71 -> 0.49804221 | G18: =(1-Parameters!$B$4)^Parameters!B$71*G17+D17*Parameters!B$71-Parameters!$B$5*D17^2/G17*Parameters!B$71 -> 3.8208072 | H18: =MAX(H17 * (1-Parameters!$B$4) ^ Parameters!B$71 + (LN(1+EXP(Parameters!$B$21*(-B17+0.004)))/Parameters!$B$21 -0.004) * Parameters!B$71,0) -> 0.013607759 | I18: =I17*(1+Parameters!$B$52)^Parameters!B$71 -> 8.497614 | J18: =J17*(1+Parameters!$B$54)^Parameters!B$71 -> 11.944697 | K18: =I18*J18*EXP(-Parameters!$B$43*'6states'!A18)*(Parameters!$B$38/Parameters!$B$39*('6states'!E18+'6states'!H18)/Parameters!$E$25*(EXP(-Parameters!$B$39*Parameters!$E$25*'6states'!H18/('6states'!E18+'6states'!H18))-EXP(-Parameters!$B$39*Parameters!$E$25)) + Parameters!$B$40*'6states'!E18) -> 26.748415 | L18: =L17+K18*Parameters!B$71 -> 2724.6883 | M18: =L18*Parameters!$B$46 -> 1.634813 | N18: =EXP(-Parameters!$B$47/2*M18^2) -> 0.97349775 | O18: =MAX((Parameters!$B$63 + Parameters!$B$31*'6states'!A18 - '6states'!L18 + Parameters!$B$48/Parameters!$B$46)/Parameters!B$63,1) -> 7.4022341 | P18: =Parameters!B$62*EXP(-Parameters!B$61*A18) -> 0.34261525 | Q18: =(1-Parameters!B$62)*O18^-Parameters!B$64 -> 0.40929244 | R18: =Parameters!B$62*EXP(-Parameters!B$61*A18)+(1-Parameters!B$62)*O18^-Parameters!B$64 -> 0.75190769 | S18: =1-R18/Parameters!$B$12 -> 0.62404615 | T18: =1/(1-S18) -> 2.659901 | U18: =(Parameters!$B$19*(E18+Parameters!$B$20)^S18+Parameters!$B$18*F18^S18)^(1/S18) -> 0.42067358 | V18: =(Parameters!$B$10*G18^Parameters!$B$9+Parameters!$B$11*U18^Parameters!$B$9)^(Parameters!$B$7/Parameters!$B$9)*N18 -> 1.4205644 | W18: =V18 - C18 - D18 - LN(1+EXP(Parameters!$B$21*B18))/Parameters!$B$21 - IF(B18>0, 0,Parameters!$B$6*B18^2/E18) -> 1.1178341 | X18: =EXP(-Parameters!$B$56*A18) -> 0.80945022 | Y18: =IF(W18>0,W18^(1-Parameters!$B$53)/(1-Parameters!$B$53)*X18*Parameters!$B$71,-10+W18*1000) -> -2.224283 | AA18: =B18/E18-B17/E17 -> -0.042925288 | AB18: =C18/F18-C17/F17 -> -0.00054108154 | AC18: =D18/G18-D17/G17 -> 0.0017081238 | AD18: =X18*(AA18^2+AB18^2+AC18^2) -> 0.0014940758 | AE18: =B18/E18-2*B17/E17+B16/E16 -> -0.018681703 | AF18: =C18/F18-2*C17/F17+C16/F16 -> 0.0011824614 | AG18: =D18/G18-2*D17/G17+D16/G16 -> -2.6533396e-05 | AH18: =X18*(AE18^2+AF18^2+AG18^2) -> 0.00028363537 | AM18: =H18*I18*J18 -> 1.381207 | AN18: =E18*I18*J18 -> 38.414859 | AO18: =U18*I18*J18 -> 42.698968 | AP18: =V18*J18*I18 -> 144.18931 | AQ18: =-X18*V18*W18^(-Parameters!B$53)*Parameters!B$47*Parameters!B$46*M18 -> -1.9505498e-05 | AR18: =1000*EXP(-(Parameters!$B$55)*'6states'!A18)*AP18*Parameters!B$47*Parameters!B$46*M18 -> 1.7391464 | AS18: =SUM(AR18:AR$204)*EXP(Parameters!$B$55*A18) -> 239.11817 | AT18: =(B18+C18+D18)/V18 -> 0.21174558 | AU18: =(1/$S18-1/Parameters!$B$13) * LN(Parameters!$B$18) / LN(O18) -> 0.23658832 | AV18: =(Parameters!$B$18*'6states'!S18^+Parameters!$B$19*Parameters!$B$25^'6states'!S18)^((1-'6states'!S18)/'6states'!S18)*Parameters!$B$18*Parameters!$B$26^('6states'!S18-1) -> 0.22581752 | AW18: =(LN(AV18)-LN(AV$4))/ LN(O18) -> 0.2768759 | AX18: =1-2^-AU18 -> 0.15124994 | AY18: =1-2^-AV18 -> 0.14488967 | AZ18: =(1/$S18-1/Parameters!$B$13) * LN(Parameters!$B$18) / A18 -> 0.033828444
